Workbook
Name _?: #N/A
Name ______R3_t: #N/A
Name _￡A￡´1: #N/A
Name _108_???14: #N/A
Name _109_???14: #N/A
Name _110_???14: #N/A
Name _111_???14: #N/A
Name _114_???15: #N/A
Name _115_???15: #N/A
Name _116_???15: #N/A
Name _117_???15: #N/A
Name _120_???16: #N/A
Name _121_???16: #N/A
Name _122_???16: #N/A
Name _123_???16: #N/A
Name _126_???17: #N/A
Name _127_???17: #N/A
Name _128_???17: #N/A
Name _129_???17: #N/A
Name _132_???6: #N/A
Name _133_???6: #N/A
Name _134_???6: #N/A
Name _135_???6: #N/A
Name _138_???7: #N/A
Name _139_???7: #N/A
Name _14_???: #N/A
Name _140_???7: #N/A
Name _141_???7: #N/A
Name _164_??1: #N/A
Name _165_??1: #N/A
Name _166_??1: #N/A
Name _167_??1: #N/A
Name _210_??M: #N/A
Name _211_??M: #N/A
Name _212_??M: #N/A
Name _213_??M: #N/A
Name _216_??MD?: #N/A
Name _217_??MD?: #N/A
Name _218_??MD?: #N/A
Name _219_??MD?: #N/A
Name _232_???14: #N/A
Name _243_???15: #N/A
Name _254_???16: #N/A
Name _265_???17: #N/A
Name _268K1_: #N/A
Name _27_???: #N/A
Name _270k113_: {"구분",0,"Auto","Auto","";"발의부서",0,"Auto","Auto",""}
Name _270k113__1: {"구분",0,"Auto","Auto","";"발의부서",0,"Auto","Auto",""}
Name _270k113__1_1: {"구분",0,"Auto","Auto","";"발의부서",0,"Auto","Auto",""}
Name _270k113__2: {"구분",0,"Auto","Auto","";"발의부서",0,"Auto","Auto",""}
Name _270k113__2_1: {"구분",0,"Auto","Auto","";"발의부서",0,"Auto","Auto",""}
Name _270k113__3: {"구분",0,"Auto","Auto","";"발의부서",0,"Auto","Auto",""}
Name _274K150_: {"994시행","SUM(994시행)","YNNNN",FALSE;"9일분기시행","SUM(9일분기시행)","YNNNN",FALSE;"이분기","SUM(이분기)","YNNNN",FALSE}
Name _274K150__1: {"994시행","SUM(994시행)","YNNNN",FALSE;"9일분기시행","SUM(9일분기시행)","YNNNN",FALSE;"이분기","SUM(이분기)","YNNNN",FALSE}
Name _274K150__1_1: {"994시행","SUM(994시행)","YNNNN",FALSE;"9일분기시행","SUM(9일분기시행)","YNNNN",FALSE;"이분기","SUM(이분기)","YNNNN",FALSE}
Name _274K150__2: {"994시행","SUM(994시행)","YNNNN",FALSE;"9일분기시행","SUM(9일분기시행)","YNNNN",FALSE;"이분기","SUM(이분기)","YNNNN",FALSE}
Name _274K150__2_1: {"994시행","SUM(994시행)","YNNNN",FALSE;"9일분기시행","SUM(9일분기시행)","YNNNN",FALSE;"이분기","SUM(이분기)","YNNNN",FALSE}
Name _274K150__3: {"994시행","SUM(994시행)","YNNNN",FALSE;"9일분기시행","SUM(9일분기시행)","YNNNN",FALSE;"이분기","SUM(이분기)","YNNNN",FALSE}
Name _276_???6: #N/A
Name _28_???: #N/A

Sheet 目录1
A1: 目 录
A2: 项目信息 | B2: =HYPERLINK("#'"&A2&"'!A1",A2)
A3: 辅助检查汇总表 | B3: =HYPERLINK("#'"&A3&"'!A1",A3)
A4: 历资表 | B4: =HYPERLINK("#'"&A4&"'!A1",A4)
A5: 历利表 | B5: =HYPERLINK("#'"&A5&"'!A1",A5)
A6: 历现表 | B6: =HYPERLINK("#'"&A6&"'!A1",A6)
A7: 历资调整后表 | B7: =HYPERLINK("#'"&A7&"'!A1",A7)
A8: 历利调整后表 | B8: =HYPERLINK("#'"&A8&"'!A1",A8)
A9: 评估结果汇总表 | B9: =HYPERLINK("#'"&A9&"'!A1",A9)
A10: 净现金流计算表 | B10: =HYPERLINK("#'"&A10&"'!A1",A10)
A11: 主要产品及服务 | B11: =HYPERLINK("#'"&A11&"'!A1",A11)
A12: 营业收入表 | B12: =HYPERLINK("#'"&A12&"'!A1",A12)
A13: 营业收入附表 | B13: =HYPERLINK("#'"&A13&"'!A1",A13)
... A42: 付息负债明细表 | B42: =HYPERLINK("#'"&A42&"'!A1",A42)

Sheet 目录2
A1: 目 录 导 航
N3: =HYPERLINK("#'历资表'!A1","历资表") | P3: =HYPERLINK("#'历利表'!A1","历利表") | R3: =HYPERLINK("#'历现表'!A1","历现表")
N4: ↓ | P4: ↓
N5: =HYPERLINK("#'历资调整后表'!A1","历资调整后表") | P5: =HYPERLINK("#'历利调整后表'!A1","历利调整后表")
N6: ↓ | P6: ↓
F7: 折旧摊销、资本性支出表 | N7: =HYPERLINK("#'营运资金表'!A1","营运资金表") | X7: =HYPERLINK("#'溢余资产、非经营资产负债表'!A1","溢余资产、非经营资产负债表") | AB7: =HYPERLINK("#'付息负债明细表'!A1","付息负债明细表") | AD7: =HYPERLINK("#'长期股权投资表'!A1","长期股权投资表")
H8: ↓ | O8: ↓ | Y8: ↓ | AB8: ↓ | AD8: ↓
B9: =HYPERLINK("#'折现率计算表'!A1","折现率计算表") | C9: → | D9: =HYPERLINK("#'净现金流计算表'!A1","净现金流计算表")
D10: ↑ | F10: ↑ | H10: ↑ | J10: ↑ | L10: ↑ | N10: ↑ | P10: ↑ | R10: ↑ | T10: ↑ | V10: ↑ | X10: ↑ | Z10: ↑ | AB10: ↑ | AD10: ↑ | AF10: ↑ | AH10: ↑ | AJ10: ↑ | AL10: ↑
D11: =HYPERLINK("#'营业收入表'!A1","营业收入表") | F11: =HYPERLINK("#'营业成本表'!A1","营业成本表") | H11: =HYPERLINK("#'税金及附加表'!A1","税金及附加表") | J11: =HYPERLINK("#'销售费用表'!A1","销售费用表") | L11: =HYPERLINK("#'管理费用表'!A1","管理费用表") | N11: =HYPERLINK("#'研发费用表'!A1","研发费用表") | P11: =HYPERLINK("#'财务费用表'!A1","财务费用表") | R11: =HYPERLINK("#'其他收益表'!A1","其他收益表") | T11: =HYPERLINK("#'投资收益表'!A1","投资收益表") | V11: =HYPERLINK("#'汇兑收益表'!A1","汇兑收益表") | X11: =HYPERLINK("#'净敞口套期收益表'!A1","净敞口套期收益表") | Z11: =HYPERLINK("#'公允价值变动收益表'!A1","公允价值变动收益表") | AB11: =HYPERLINK("#'信用减值损失表'!A1","信用减值损失表") | AD11: =HYPERLINK("#'资产减值损失表'!A1","资产减值损失表") | AF11: =HYPERLINK("#'资产处置收益表'!A1","资产处置收益表") | AH11: =HYPERLINK("#'营业外收入表'!A1","营业外收入表") | AJ11: =HYPERLINK("#'营业外支出表'!A1","营业外支出表") | AL11: =HYPERLINK("#'所得税表'!A1","所得税表")
D12: ↑ | F12: ↑ | H12: ↑ | J12: ↑↓ | L12: ↑↓ | N12: ↑↓
D13: =HYPERLINK("#'营业收入附表'!A1","营业收入附表") | F13: =HYPERLINK("#'营业成本附表'!A1","营业成本附表") | H13: =HYPERLINK("#'增值税表'!A1","增值税表") | J13: =HYPERLINK("#'折旧摊销、资本性支出表'!A1","折旧摊销、资本性支出表") | O13: ← → | P13: =HYPERLINK("#'制造费用表'!A1","制造费用表")
D14: ↑ | F14: ↑ | J14: ↑ | L14: ↑
D15: =HYPERLINK("#'主要产品及服务'!A1","主要产品及服务") | H15: =HYPERLINK("#'人工成本表'!A1","人工成本表") | J15: =HYPERLINK("#'折旧摊销附表'!A1","折旧摊销附表") | L15: =HYPERLINK("#'资本性支出附表'!A1","资本性支出附表")

Sheet 撤销保护记录
A1: 申请日期 | B1: Sheet名称 | C1: 撤销保护的原因

Sheet 项目信息
A1: 收益法预测表 | C1: =HYPERLINK("#目录1!A1","返回目录")
A2: 评估基准日：{{VALUATION_BASE_DATE}}
A3: ="被评估单位："&项目信息!B5&"" | B3: ="金额单位："&项目信息!B8&""
A4: 项目信息 | B4: 值
A5: 被评估企业 | B5: {{COMPANY_NAME}}
A6: 企业类型 | B6: 待补充评估参数
A7: 评估基准日 | B7: {{VALUATION_BASE_DATE}}
A8: 单位 | B8: 万元
A9: 被评估单位是否永续 | B9: 待补充评估参数
A10: 是否永续增长 | B10: 待补充评估参数
A11: 永续增长率 | B11: 待补充评估参数
A12: 最后一期评估期 | B12: 待补充评估参数
A13: 现金流模型 | B13: 待补充评估参数
A14: 折现方式 | B14: 待补充评估参数
A15: 使用资本结构 | B15: 待补充评估参数
... A17: 项目类型 | B17: 待补充评估参数

Sheet 辅助检查汇总表
A1: 辅助检查汇总表 | O1: =HYPERLINK("#目录1!A1","返回目录")
A2: 评估基准日：{{VALUATION_BASE_DATE}}
A3: ="被评估单位："&项目信息!B5&"" | N3: ="金额单位："&项目信息!B8&""
A5: 历资表
A6: =历资表!A101 | B6: =历资表!B101 | C6: =历资表!C101 | D6: =历资表!D101 | E6: =历资表!E101
A8: 历资调整后表
A9: =历资调整后表!A101 | B9: =历资调整后表!B101 | C9: =历资调整后表!C101 | D9: =历资调整后表!D101 | E9: =历资调整后表!E101 | F9: =历资调整后表!F101 | G9: =历资调整后表!G101 | H9: =历资调整后表!H101 | ... N9: =历资调整后表!N101
A11: 评估结果汇总表
A12: =评估结果汇总表!A32 | B12: =评估结果汇总表!B32
A14: 营业收入表
A15: =营业收入表!A19 | B15: =营业收入表!B19 | C15: =营业收入表!C19 | D15: =营业收入表!D19 | E15: =营业收入表!E19 | F15: =营业收入表!F19 | G15: =营业收入表!G19 | H15: =营业收入表!H19 | ... M15: =营业收入表!M19
A16: =营业收入表!A20 | B16: =营业收入表!B20 | C16: =营业收入表!C20 | D16: =营业收入表!D20 | E16: =营业收入表!E20 | F16: =营业收入表!F20 | G16: =营业收入表!G20 | H16: =营业收入表!H20 | ... M16: =营业收入表!M20
A17: =营业收入表!A21 | B17: =营业收入表!B21 | C17: =营业收入表!C21 | D17: =营业收入表!D21 | E17: =营业收入表!E21 | F17: =营业收入表!F21 | G17: =营业收入表!G21 | H17: =营业收入表!H21 | ... M17: =营业收入表!M21
A18: =营业收入表!A22 | B18: =营业收入表!B22 | C18: =营业收入表!C22 | D18: =营业收入表!D22 | E18: =营业收入表!E22 | F18: =营业收入表!F22 | G18: =营业收入表!G22 | H18: =营业收入表!H22 | ... M18: =营业收入表!M22
A19: =营业收入表!A23 | B19: =营业收入表!B23 | C19: =营业收入表!C23 | D19: =营业收入表!D23 | E19: =营业收入表!E23 | F19: =营业收入表!F23 | G19: =营业收入表!G23 | H19: =营业收入表!H23 | ... M19: =营业收入表!M23
A20: =营业收入表!A24 | B20: =营业收入表!B24 | C20: =营业收入表!C24 | D20: =营业收入表!D24 | E20: =营业收入表!E24 | F20: =营业收入表!F24 | G20: =营业收入表!G24 | H20: =营业收入表!H24 | ... M20: =营业收入表!M24
A21: =营业收入表!A25 | B21: =营业收入表!B25 | C21: =营业收入表!C25 | D21: =营业收入表!D25 | E21: =营业收入表!E25 | F21: =营业收入表!F25 | G21: =营业收入表!G25 | H21: =营业收入表!H25 | ... M21: =营业收入表!M25
A23: 营业收入附表
A24: =营业收入附表!A25 | B24: =营业收入附表!B25 | C24: =营业收入附表!C25 | D24: =营业收入附表!D25 | E24: =营业收入附表!E25 | F24: =营业收入附表!F25
A25: =营业收入附表!A26 | B25: =营业收入附表!B26 | C25: =营业收入附表!C26 | D25: =营业收入附表!D26 | E25: =营业收入附表!E26 | F25: =营业收入附表!F26
A26: =营业收入附表!A27 | B26: =营业收入附表!B27 | C26: =营业收入附表!C27 | D26: =营业收入附表!D27 | E26: =营业收入附表!E27 | F26: =营业收入附表!F27
A28: 营业成本表
A29: =营业成本表!A19 | B29: =营业成本表!B19 | C29: =营业成本表!C19 | D29: =营业成本表!D19 | E29: =营业成本表!E19 | F29: =营业成本表!F19 | G29: =营业成本表!G19 | H29: =营业成本表!H19 | ... M29: =营业成本表!M19
A30: =营业成本表!A20 | B30: =营业成本表!B20 | C30: =营业成本表!C20 | D30: =营业成本表!D20 | E30: =营业成本表!E20 | F30: =营业成本表!F20 | G30: =营业成本表!G20 | H30: =营业成本表!H20 | ... M30: =营业成本表!M20
A31: =营业成本表!A21 | B31: =营业成本表!B21 | C31: =营业成本表!C21 | D31: =营业成本表!D21 | E31: =营业成本表!E21 | F31: =营业成本表!F21 | G31: =营业成本表!G21 | H31: =营业成本表!H21 | ... M31: =营业成本表!M21
A32: =营业成本表!A22 | B32: =营业成本表!B22 | C32: =营业成本表!C22 | D32: =营业成本表!D22 | E32: =营业成本表!E22 | F32: =营业成本表!F22 | G32: =营业成本表!G22 | H32: =营业成本表!H22 | ... M32: =营业成本表!M22
A33: =营业成本表!A23 | B33: =营业成本表!B23 | C33: =营业成本表!C23 | D33: =营业成本表!D23 | E33: =营业成本表!E23 | F33: =营业成本表!F23 | G33: =营业成本表!G23 | H33: =营业成本表!H23 | ... M33: =营业成本表!M23
A34: =营业成本表!A24 | B34: =营业成本表!B24 | C34: =营业成本表!C24 | D34: =营业成本表!D24 | E34: =营业成本表!E24 | F34: =营业成本表!F24 | G34: =营业成本表!G24 | H34: =营业成本表!H24 | ... M34: =营业成本表!M24
A35: =营业成本表!A25 | B35: =营业成本表!B25 | C35: =营业成本表!C25 | D35: =营业成本表!D25 | E35: =营业成本表!E25 | F35: =营业成本表!F25 | G35: =营业成本表!G25 | H35: =营业成本表!H25 | ... M35: =营业成本表!M25
A36: =营业成本表!A26 | B36: =营业成本表!B26 | C36: =营业成本表!C26 | D36: =营业成本表!D26 | E36: =营业成本表!E26 | F36: =营业成本表!F26 | G36: =营业成本表!G26 | H36: =营业成本表!H26 | ... M36: =营业成本表!M26
A37: =营业成本表!A27 | B37: =营业成本表!B27 | C37: =营业成本表!C27 | D37: =营业成本表!D27 | E37: =营业成本表!E27 | F37: =营业成本表!F27 | G37: =营业成本表!G27 | H37: =营业成本表!H27 | ... M37: =营业成本表!M27
A39: 营业成本附表
A40: =营业成本附表!A33 | B40: =营业成本附表!B33 | C40: =营业成本附表!C33 | D40: =营业成本附表!D33 | E40: =营业成本附表!E33 | F40: =营业成本附表!F33
A41: =营业成本附表!A34 | B41: =营业成本附表!B34 | C41: =营业成本附表!C34 | D41: =营业成本附表!D34 | E41: =营业成本附表!E34 | F41: =营业成本附表!F34
A42: =营业成本附表!A35 | B42: =营业成本附表!B35 | C42: =营业成本附表!C35 | D42: =营业成本附表!D35 | E42: =营业成本附表!E35 | F42: =营业成本附表!F35
A43: =营业成本附表!A36 | B43: =营业成本附表!B36 | C43: =营业成本附表!C36 | D43: =营业成本附表!D36 | E43: =营业成本附表!E36 | F43: =营业成本附表!F36 | G43: =营业成本附表!G36 | H43: =营业成本附表!H36 | ... M43: =营业成本附表!M36
A44: =营业成本附表!A37 | B44: =营业成本附表!B37 | C44: =营业成本附表!C37 | D44: =营业成本附表!D37 | E44: =营业成本附表!E37 | F44: =营业成本附表!F37 | G44: =营业成本附表!G37 | H44: =营业成本附表!H37 | ... M44: =营业成本附表!M37
A45: =营业成本附表!A38 | B45: =营业成本附表!B38 | C45: =营业成本附表!C38 | D45: =营业成本附表!D38 | E45: =营业成本附表!E38 | F45: =营业成本附表!F38 | G45: =营业成本附表!G38 | H45: =营业成本附表!H38 | ... M45: =营业成本附表!M38
A46: =营业成本附表!A39 | B46: =营业成本附表!B39 | C46: =营业成本附表!C39 | D46: =营业成本附表!D39 | E46: =营业成本附表!E39 | F46: =营业成本附表!F39 | G46: =营业成本附表!G39 | H46: =营业成本附表!H39 | ... M46: =营业成本附表!M39
A48: 制造费用表
...

Sheet 历资表
A1: 历史资产负债表 | F1: =HYPERLINK("#目录1!A1","返回目录")
A2: 评估基准日：{{VALUATION_BASE_DATE}}
A3: ="被评估单位："&项目信息!B5&"" | E3: ="金额单位："&项目信息!B8&""
A4: 项目\年份 | B4: 2022年度 | C4: 2023年度 | D4: 2024年度 | E4: 2025年1-6月
A6: 流动资产：
A7: 货币资金
A8: 结算备付金
A9: 拆出资金
A10: 交易性金融资产
A11: 衍生金融资产
A12: 应收票据
A13: 应收账款
A14: 应收款项融资
A15: 预付款项
A16: 应收保费
A17: 应收分保账款
... A25: 其他流动资产
A26: 一、流动资产合计 | B26: =SUM(B7:B25) | C26: =SUM(C7:C25) | D26: =SUM(D7:D25) | E26: =SUM(E7:E25)
A27: 非流动资产：
A28: 可供出售金融资产
A29: 债权投资
A30: 其他债权投资
A31: 长期应收款
A32: 长期股权投资
A33: 其他权益工具投资
A34: 其他非流动金融资产
A35: 投资性房地产
A36: 固定资产
A37: 在建工程
A38: 工程物资
... A45: 其他非流动资产
A46: 二、非流动资产合计 | B46: =SUM(B28:B45) | C46: =SUM(C28:C45) | D46: =SUM(D28:D45) | E46: =SUM(E28:E45)
A47: 三、资产总计 | B47: =B26+B46 | C47: =C26+C46 | D47: =D26+D46 | E47: =E26+E46
A48: 流动负债：
A49: 短期借款
A50: 向中央银行借款
A51: 拆入资金
A52: 交易性金融负债
A53: 衍生金融负债
A54: 应付票据
...

Sheet 历利表
A1: 历史利润表 | F1: =HYPERLINK("#目录1!A1","返回目录")
A2: 评估基准日：{{VALUATION_BASE_DATE}}
A3: ="被评估单位："&项目信息!B5&"" | E3: ="金额单位："&项目信息!B8&""
A4: 项目\年份 | B4: 2022年度 | C4: 2023年度 | D4: 2024年度 | E4: 2025年1-6月
A6: 一、营业总收入 | B6: =B7+SUM(B10:B12) | C6: =C7+SUM(C10:C12) | D6: =D7+SUM(D10:D12) | E6: =E7+SUM(E10:E12)
A7: 其中：营业收入 | B7: =B8+B9 | C7: =C8+C9 | D7: =D8+D9 | E7: =E8+E9
A8: 其中：主营业务收入
A9: 其他业务收入
A10: 利息收入
A11: 已赚保费
A12: 手续费及佣金收入
A13: 二、营业总成本 | B13: =B14+SUM(B17:B28) | C13: =C14+SUM(C17:C28) | D13: =D14+SUM(D17:D28) | E13: =E14+SUM(E17:E28)
A14: 其中：营业成本 | B14: =B15+B16 | C14: =C15+C16 | D14: =D15+D16 | E14: =E15+E16
A15: 其中：主营业务成本
A16: 其他业务成本
A17: 利息支出
A18: 手续费及佣金支出
A19: 退保金
A20: 赔付支出净额
A21: 提取保险责任准备金净额
A22: 保单红利支出
A23: 分保费用
A24: 税金及附加
A25: 销售费用
A26: 管理费用
... A40: 资产处置收益（损失以“-”号填列）
A41: 三、营业利润 | B41: =B6-B13+SUM(B31:B32)+SUM(B35:B40) | C41: =C6-C13+SUM(C31:C32)+SUM(C35:C40) | D41: =D6-D13+SUM(D31:D32)+SUM(D35:D40) | E41: =E6-E13+SUM(E31:E32)+SUM(E35:E40)
A42: 加：营业外收入
A43: 减：营业外支出
A44: 四、利润总额 | B44: =B41+B42-B43 | C44: =C41+C42-C43 | D44: =D41+D42-D43 | E44: =E41+E42-E43
A45: 减: 所得税费用
A46: 五、净利润 | B46: =B44-B45 | C46: =C44-C45 | D46: =D44-D45 | E46: =E44-E45
A47: （一）持续经营净利润
A48: （二）终止经营净利润
A49: 减：少数股东损益
A50: 六、归属于母公司损益 | B50: =B46-B49 | C50: =C46-C49 | D50: =D46-D49 | E50: =E46-E49

Sheet 历现表
A1: 历史现金流量表 | F1: =HYPERLINK("#目录1!A1","返回目录")
A2: 评估基准日：{{VALUATION_BASE_DATE}}
A3: ="被评估单位："&项目信息!B5&"" | E3: ="金额单位："&项目信息!B8&""
A4: 项目\年份 | B4: 2022年度 | C4: 2023年度 | D4: 2024年度 | E4: 2025年1-6月
A5: 一、经营活动产生的现金流量：
A6: 销售商品、提供劳务收到的现金
A7: 收到的税费返还
A8: 收到其他与经营活动有关的现金
A9: 经营活动现金流入小计 | B9: =SUM(B6:B8) | C9: =SUM(C6:C8) | D9: =SUM(D6:D8) | E9: =SUM(E6:E8)
A10: 购买商品、接受劳务支付的现金
A11: 支付给职工以及为职工支付的现金
A12: 支付的各项税费
A13: 支付其他与经营活动有关的现金
A14: 经营活动现金流出小计 | B14: =SUM(B10:B13) | C14: =SUM(C10:C13) | D14: =SUM(D10:D13) | E14: =SUM(E10:E13)
A15: 经营活动产生的现金流量净额 | B15: =B9-B14 | C15: =C9-C14 | D15: =D9-D14 | E15: =E9-E14
A16: 二、投资活动产生的现金流量：
A17: 收回投资收到的现金
A18: 取得投资收益收到的现金
A19: 处置固定资产、无形资产和其他长期资产收回的现金净额
A20: 处置子公司及其他营业单位收到的现金净额
A21: 收到其他与投资活动有关的现金
A22: 投资活动现金流入小计 | B22: =SUM(B17:B21) | C22: =SUM(C17:C21) | D22: =SUM(D17:D21) | E22: =SUM(E17:E21)
A23: 购建固定资产、无形资产和其他长期资产支付的现金
A24: 投资支付的现金
A25: 取得子公司及其他营业单位支付的现金净额
A26: 支付其他与投资活动有关的现金
A27: 投资活动现金流出小计 | B27: =SUM(B23:B26) | C27: =SUM(C23:C26) | D27: =SUM(D23:D26) | E27: =SUM(E23:E26)
A28: 投资活动产生的现金流量净额 | B28: =B22-B27 | C28: =C22-C27 | D28: =D22-D27 | E28: =E22-E27
A29: 三、筹资活动产生的现金流量：
A30: 吸收投资收到的现金
A31: 取得借款收到的现金
A32: 收到其他与筹资活动有关的现金
A33: 筹资活动现金流入小计 | B33: =SUM(B30:B32) | C33: =SUM(C30:C32) | D33: =SUM(D30:D32) | E33: =SUM(E30:E32)
A34: 偿还债务支付的现金
A35: 分配股利、利润或偿付利息支付的现金
A36: 支付其他与筹资活动有关的现金
A37: 筹资活动现金流出小计 | B37: =SUM(B34:B36) | C37: =SUM(C34:C36) | D37: =SUM(D34:D36) | E37: =SUM(E34:E36)
A38: 筹资活动产生的现金流量净额 | B38: =B33-B37 | C38: =C33-C37 | D38: =D33-D37 | E38: =E33-E37
A39: 四、汇率变动对现金及现金等价物的影响
A40: 五、现金及现金等价物净增加额 | B40: =B15+B28+B38+B39 | C40: =C15+C28+C38+C39 | D40: =D15+D28+D38+D39 | E40: =E15+E28+E38+E39
...

Sheet 历资调整后表
A1: 历史资产负债分析调整表 | O1: =HYPERLINK("#目录1!A1","返回目录")
A2: 评估基准日：{{VALUATION_BASE_DATE}}
A3: ="被评估单位："&项目信息!B5&"" | N3: ="金额单位："&项目信息!B8&""
A4: 项目\年份 | B4: 2022年度 | E4: 2023年度 | H4: 2024年度 | K4: 2025年1-6月 | N4: 调整分析说明
B5: 账面值/审定值 | C5: 其中：非经营性资产，或者重分类调整 | D5: 调整后经营性资产 | E5: 账面值/审定值 | F5: 其中：非经营性资产，或者重分类调整 | G5: 调整后经营性资产 | H5: 账面值/审定值 | I5: 其中：非经营性资产，或者重分类调整 | J5: 调整后经营性资产 | K5: 账面值/审定值 | L5: 其中：非经营性资产，或者重分类调整 | M5: 调整后经营性资产
A6: =历资表!A6
A7: =历资表!A7 | B7: =历资表!B7 | D7: =B7-C7 | E7: =历资表!C7 | G7: =E7-F7 | H7: =历资表!D7 | J7: =H7-I7 | K7: =历资表!E7 | M7: =K7-L7
A8: =历资表!A8 | B8: =历资表!B8 | D8: =B8-C8 | E8: =历资表!C8 | G8: =E8-F8 | H8: =历资表!D8 | J8: =H8-I8 | K8: =历资表!E8 | M8: =K8-L8
A9: =历资表!A9 | B9: =历资表!B9 | D9: =B9-C9 | E9: =历资表!C9 | G9: =E9-F9 | H9: =历资表!D9 | J9: =H9-I9 | K9: =历资表!E9 | M9: =K9-L9
A10: =历资表!A10 | B10: =历资表!B10 | D10: =B10-C10 | E10: =历资表!C10 | G10: =E10-F10 | H10: =历资表!D10 | J10: =H10-I10 | K10: =历资表!E10 | M10: =K10-L10
A11: =历资表!A11 | B11: =历资表!B11 | D11: =B11-C11 | E11: =历资表!C11 | G11: =E11-F11 | H11: =历资表!D11 | J11: =H11-I11 | K11: =历资表!E11 | M11: =K11-L11
A12: =历资表!A12 | B12: =历资表!B12 | D12: =B12-C12 | E12: =历资表!C12 | G12: =E12-F12 | H12: =历资表!D12 | J12: =H12-I12 | K12: =历资表!E12 | M12: =K12-L12
A13: =历资表!A13 | B13: =历资表!B13 | D13: =B13-C13 | E13: =历资表!C13 | G13: =E13-F13 | H13: =历资表!D13 | J13: =H13-I13 | K13: =历资表!E13 | M13: =K13-L13
A14: =历资表!A14 | B14: =历资表!B14 | D14: =B14-C14 | E14: =历资表!C14 | G14: =E14-F14 | H14: =历资表!D14 | J14: =H14-I14 | K14: =历资表!E14 | M14: =K14-L14
A15: =历资表!A15 | B15: =历资表!B15 | D15: =B15-C15 | E15: =历资表!C15 | G15: =E15-F15 | H15: =历资表!D15 | J15: =H15-I15 | K15: =历资表!E15 | M15: =K15-L15
A16: =历资表!A16 | B16: =历资表!B16 | D16: =B16-C16 | E16: =历资表!C16 | G16: =E16-F16 | H16: =历资表!D16 | J16: =H16-I16 | K16: =历资表!E16 | M16: =K16-L16
A17: =历资表!A17 | B17: =历资表!B17 | D17: =B17-C17 | E17: =历资表!C17 | G17: =E17-F17 | H17: =历资表!D17 | J17: =H17-I17 | K17: =历资表!E17 | M17: =K17-L17
A18: =历资表!A18 | B18: =历资表!B18 | D18: =B18-C18 | E18: =历资表!C18 | G18: =E18-F18 | H18: =历资表!D18 | J18: =H18-I18 | K18: =历资表!E18 | M18: =K18-L18
A19: =历资表!A19 | B19: =历资表!B19 | D19: =B19-C19 | E19: =历资表!C19 | G19: =E19-F19 | H19: =历资表!D19 | J19: =H19-I19 | K19: =历资表!E19 | L19: =K19 | M19: =K19-L19
A20: =历资表!A20 | B20: =历资表!B20 | D20: =B20-C20 | E20: =历资表!C20 | G20: =E20-F20 | H20: =历资表!D20 | J20: =H20-I20 | K20: =历资表!E20 | M20: =K20-L20
A21: =历资表!A21 | B21: =历资表!B21 | D21: =B21-C21 | E21: =历资表!C21 | G21: =E21-F21 | H21: =历资表!D21 | J21: =H21-I21 | K21: =历资表!E21 | M21: =K21-L21
A22: =历资表!A22 | B22: =历资表!B22 | D22: =B22-C22 | E22: =历资表!C22 | G22: =E22-F22 | H22: =历资表!D22 | J22: =H22-I22 | K22: =历资表!E22 | M22: =K22-L22
A23: =历资表!A23 | B23: =历资表!B23 | D23: =B23-C23 | E23: =历资表!C23 | G23: =E23-F23 | H23: =历资表!D23 | J23: =H23-I23 | K23: =历资表!E23 | M23: =K23-L23
A24: =历资表!A24 | B24: =历资表!B24 | D24: =B24-C24 | E24: =历资表!C24 | G24: =E24-F24 | H24: =历资表!D24 | J24: =H24-I24 | K24: =历资表!E24 | M24: =K24-L24
A25: =历资表!A25 | B25: =历资表!B25 | D25: =B25-C25 | E25: =历资表!C25 | G25: =E25-F25 | H25: =历资表!D25 | J25: =H25-I25 | K25: =历资表!E25 | M25: =K25-L25
A26: =历资表!A26 | B26: =历资表!B26 | C26: =SUM(C7:C25) | D26: =B26-C26 | E26: =历资表!C26 | F26: =SUM(F7:F25) | G26: =E26-F26 | H26: =历资表!D26 | I26: =SUM(I7:I25) | J26: =H26-I26 | K26: =历资表!E26 | L26: =SUM(L7:L25) | M26: =K26-L26
A27: =历资表!A27
A28: =历资表!A28 | B28: =历资表!B28 | D28: =B28-C28 | E28: =历资表!C28 | G28: =E28-F28 | H28: =历资表!D28 | J28: =H28-I28 | K28: =历资表!E28 | M28: =K28-L28
A29: =历资表!A29 | B29: =历资表!B29 | D29: =B29-C29 | E29: =历资表!C29 | G29: =E29-F29 | H29: =历资表!D29 | J29: =H29-I29 | K29: =历资表!E29 | M29: =K29-L29
A30: =历资表!A30 | B30: =历资表!B30 | D30: =B30-C30 | E30: =历资表!C30 | G30: =E30-F30 | H30: =历资表!D30 | J30: =H30-I30 | K30: =历资表!E30 | M30: =K30-L30
A31: =历资表!A31 | B31: =历资表!B31 | D31: =B31-C31 | E31: =历资表!C31 | G31: =E31-F31 | H31: =历资表!D31 | J31: =H31-I31 | K31: =历资表!E31 | M31: =K31-L31
A32: =历资表!A32 | B32: =历资表!B32 | D32: =B32-C32 | E32: =历资表!C32 | G32: =E32-F32 | H32: =历资表!D32 | J32: =H32-I32 | K32: =历资表!E32 | L32: =K32 | M32: =K32-L32
A33: =历资表!A33 | B33: =历资表!B33 | D33: =B33-C33 | E33: =历资表!C33 | G33: =E33-F33 | H33: =历资表!D33 | J33: =H33-I33 | K33: =历资表!E33 | M33: =K33-L33
A34: =历资表!A34 | B34: =历资表!B34 | D34: =B34-C34 | E34: =历资表!C34 | G34: =E34-F34 | H34: =历资表!D34 | J34: =H34-I34 | K34: =历资表!E34 | M34: =K34-L34
A35: =历资表!A35 | B35: =历资表!B35 | D35: =B35-C35 | E35: =历资表!C35 | G35: =E35-F35 | H35: =历资表!D35 | J35: =H35-I35 | K35: =历资表!E35 | M35: =K35-L35
A36: =历资表!A36 | B36: =历资表!B36 | D36: =B36-C36 | E36: =历资表!C36 | G36: =E36-F36 | H36: =历资表!D36 | J36: =H36-I36 | K36: =历资表!E36 | M36: =K36-L36
A37: =历资表!A37 | B37: =历资表!B37 | D37: =B37-C37 | E37: =历资表!C37 | G37: =E37-F37 | H37: =历资表!D37 | J37: =H37-I37 | K37: =历资表!E37 | M37: =K37-L37
A38: =历资表!A38 | B38: =历资表!B38 | D38: =B38-C38 | E38: =历资表!C38 | G38: =E38-F38 | H38: =历资表!D38 | J38: =H38-I38 | K38: =历资表!E38 | M38: =K38-L38
A39: =历资表!A39 | B39: =历资表!B39 | D39: =B39-C39 | E39: =历资表!C39 | G39: =E39-F39 | H39: =历资表!D39 | J39: =H39-I39 | K39: =历资表!E39 | M39: =K39-L39
A40: =历资表!A40 | B40: =历资表!B40 | D40: =B40-C40 | E40: =历资表!C40 | G40: =E40-F40 | H40: =历资表!D40 | J40: =H40-I40 | K40: =历资表!E40 | M40: =K40-L40
...

Sheet 历利调整后表
A1: 历史损益调整分析表 | O1: =HYPERLINK("#目录1!A1","返回目录")
A2: 评估基准日：{{VALUATION_BASE_DATE}}
A3: ="被评估单位："&项目信息!B5&"" | N3: ="金额单位："&项目信息!B8&""
A4: 项目\年份 | B4: 2022年度 | E4: 2023年度 | H4: 2024年度 | K4: 2025年1-6月 | N4: 调整分析说明
B5: 账面值/审定值 | C5: 其中：非经营性资产产生的损益 | D5: 调整后损益数据 | E5: 账面值/审定值 | F5: 其中：非经营性资产产生的损益 | G5: 调整后损益数据 | H5: 账面值/审定值 | I5: 其中：非经营性资产产生的损益 | J5: 调整后损益数据 | K5: 账面值/审定值 | L5: 其中：非经营性资产产生的损益 | M5: 调整后损益数据
A6: =历利表!A6 | B6: =历利表!B6 | C6: =C7+SUM(C10:C12) | D6: =B6-C6 | E6: =历利表!C6 | F6: =F7+SUM(F10:F12) | G6: =E6-F6 | H6: =历利表!D6 | I6: =I7+SUM(I10:I12) | J6: =H6-I6 | K6: =历利表!E6 | L6: =L7+SUM(L10:L12) | M6: =K6-L6
A7: =历利表!A7 | B7: =历利表!B7 | C7: =C8+C9 | D7: =B7-C7 | E7: =历利表!C7 | F7: =F8+F9 | G7: =E7-F7 | H7: =历利表!D7 | I7: =I8+I9 | J7: =H7-I7 | K7: =历利表!E7 | L7: =L8+L9 | M7: =K7-L7
A8: =历利表!A8 | B8: =历利表!B8 | D8: =B8-C8 | E8: =历利表!C8 | G8: =E8-F8 | H8: =历利表!D8 | J8: =H8-I8 | K8: =历利表!E8 | M8: =K8-L8
A9: =历利表!A9 | B9: =历利表!B9 | D9: =B9-C9 | E9: =历利表!C9 | G9: =E9-F9 | H9: =历利表!D9 | J9: =H9-I9 | K9: =历利表!E9 | M9: =K9-L9
A10: =历利表!A10 | B10: =历利表!B10 | D10: =B10-C10 | E10: =历利表!C10 | G10: =E10-F10 | H10: =历利表!D10 | J10: =H10-I10 | K10: =历利表!E10 | M10: =K10-L10
A11: =历利表!A11 | B11: =历利表!B11 | D11: =B11-C11 | E11: =历利表!C11 | G11: =E11-F11 | H11: =历利表!D11 | J11: =H11-I11 | K11: =历利表!E11 | M11: =K11-L11
A12: =历利表!A12 | B12: =历利表!B12 | D12: =B12-C12 | E12: =历利表!C12 | G12: =E12-F12 | H12: =历利表!D12 | J12: =H12-I12 | K12: =历利表!E12 | M12: =K12-L12
A13: =历利表!A13 | B13: =历利表!B13 | C13: =C14+SUM(C17:C28) | D13: =B13-C13 | E13: =历利表!C13 | F13: =F14+SUM(F17:F28) | G13: =E13-F13 | H13: =历利表!D13 | I13: =I14+SUM(I17:I28) | J13: =H13-I13 | K13: =历利表!E13 | L13: =L14+SUM(L17:L28) | M13: =K13-L13
A14: =历利表!A14 | B14: =历利表!B14 | C14: =C15+C16 | D14: =B14-C14 | E14: =历利表!C14 | F14: =F15+F16 | G14: =E14-F14 | H14: =历利表!D14 | I14: =I15+I16 | J14: =H14-I14 | K14: =历利表!E14 | L14: =L15+L16 | M14: =K14-L14
A15: =历利表!A15 | B15: =历利表!B15 | D15: =B15-C15 | E15: =历利表!C15 | G15: =E15-F15 | H15: =历利表!D15 | J15: =H15-I15 | K15: =历利表!E15 | M15: =K15-L15
A16: =历利表!A16 | B16: =历利表!B16 | D16: =B16-C16 | E16: =历利表!C16 | G16: =E16-F16 | H16: =历利表!D16 | J16: =H16-I16 | K16: =历利表!E16 | M16: =K16-L16
A17: =历利表!A17 | B17: =历利表!B17 | D17: =B17-C17 | E17: =历利表!C17 | G17: =E17-F17 | H17: =历利表!D17 | J17: =H17-I17 | K17: =历利表!E17 | M17: =K17-L17
A18: =历利表!A18 | B18: =历利表!B18 | D18: =B18-C18 | E18: =历利表!C18 | G18: =E18-F18 | H18: =历利表!D18 | J18: =H18-I18 | K18: =历利表!E18 | M18: =K18-L18
A19: =历利表!A19 | B19: =历利表!B19 | D19: =B19-C19 | E19: =历利表!C19 | G19: =E19-F19 | H19: =历利表!D19 | J19: =H19-I19 | K19: =历利表!E19 | M19: =K19-L19
A20: =历利表!A20 | B20: =历利表!B20 | D20: =B20-C20 | E20: =历利表!C20 | G20: =E20-F20 | H20: =历利表!D20 | J20: =H20-I20 | K20: =历利表!E20 | M20: =K20-L20
A21: =历利表!A21 | B21: =历利表!B21 | D21: =B21-C21 | E21: =历利表!C21 | G21: =E21-F21 | H21: =历利表!D21 | J21: =H21-I21 | K21: =历利表!E21 | M21: =K21-L21
A22: =历利表!A22 | B22: =历利表!B22 | D22: =B22-C22 | E22: =历利表!C22 | G22: =E22-F22 | H22: =历利表!D22 | J22: =H22-I22 | K22: =历利表!E22 | M22: =K22-L22
A23: =历利表!A23 | B23: =历利表!B23 | D23: =B23-C23 | E23: =历利表!C23 | G23: =E23-F23 | H23: =历利表!D23 | J23: =H23-I23 | K23: =历利表!E23 | M23: =K23-L23
A24: =历利表!A24 | B24: =历利表!B24 | D24: =B24-C24 | E24: =历利表!C24 | G24: =E24-F24 | H24: =历利表!D24 | J24: =H24-I24 | K24: =历利表!E24 | M24: =K24-L24
A25: =历利表!A25 | B25: =历利表!B25 | D25: =B25-C25 | E25: =历利表!C25 | G25: =E25-F25 | H25: =历利表!D25 | J25: =H25-I25 | K25: =历利表!E25 | M25: =K25-L25
A26: =历利表!A26 | B26: =历利表!B26 | D26: =B26-C26 | E26: =历利表!C26 | G26: =E26-F26 | H26: =历利表!D26 | J26: =H26-I26 | K26: =历利表!E26 | M26: =K26-L26
... A40: =历利表!A40 | B40: =历利表!B40 | D40: =B40-C40 | E40: =历利表!C40 | G40: =E40-F40 | H40: =历利表!D40 | J40: =H40-I40 | K40: =历利表!E40 | M40: =K40-L40
A41: =历利表!A41 | B41: =历利表!B41 | C41: =C6-C13+SUM(C31:C32)+SUM(C35:C40) | D41: =B41-C41 | E41: =历利表!C41 | F41: =F6-F13+SUM(F31:F32)+SUM(F35:F40) | G41: =E41-F41 | H41: =历利表!D41 | I41: =I6-I13+SUM(I31:I32)+SUM(I35:I40) | J41: =H41-I41 | K41: =历利表!E41 | L41: =L6-L13+SUM(L31:L32)+SUM(L35:L40) | M41: =K41-L41
A42: =历利表!A42 | B42: =历利表!B42 | D42: =B42-C42 | E42: =历利表!C42 | G42: =E42-F42 | H42: =历利表!D42 | J42: =H42-I42 | K42: =历利表!E42 | M42: =K42-L42
A43: =历利表!A43 | B43: =历利表!B43 | D43: =B43-C43 | E43: =历利表!C43 | G43: =E43-F43 | H43: =历利表!D43 | J43: =H43-I43 | K43: =历利表!E43 | M43: =K43-L43
A44: =历利表!A44 | B44: =历利表!B44 | C44: =C41+C42-C43 | D44: =B44-C44 | E44: =历利表!C44 | F44: =F41+F42-F43 | G44: =E44-F44 | H44: =历利表!D44 | I44: =I41+I42-I43 | J44: =H44-I44 | K44: =历利表!E44 | L44: =L41+L42-L43 | M44: =K44-L44
A45: =历利表!A45 | B45: =历利表!B45 | D45: =B45-C45 | E45: =历利表!C45 | G45: =E45-F45 | H45: =历利表!D45 | J45: =H45-I45 | K45: =历利表!E45 | M45: =K45-L45
A46: =历利表!A46 | B46: =历利表!B46 | C46: =C44-C45 | D46: =B46-C46 | E46: =历利表!C46 | F46: =F44-F45 | G46: =E46-F46 | H46: =历利表!D46 | I46: =I44-I45 | J46: =H46-I46 | K46: =历利表!E46 | L46: =L44-L45 | M46: =K46-L46
A47: =历利表!A47 | B47: =历利表!B47 | D47: =B47-C47 | E47: =历利表!C47 | G47: =E47-F47 | H47: =历利表!D47 | J47: =H47-I47 | K47: =历利表!E47 | M47: =K47-L47
A48: =历利表!A48 | B48: =历利表!B48 | D48: =B48-C48 | E48: =历利表!C48 | G48: =E48-F48 | H48: =历利表!D48 | J48: =H48-I48 | K48: =历利表!E48 | M48: =K48-L48
A49: =历利表!A49 | B49: =历利表!B49 | D49: =B49-C49 | E49: =历利表!C49 | G49: =E49-F49 | H49: =历利表!D49 | J49: =H49-I49 | K49: =历利表!E49 | M49: =K49-L49
A50: =历利表!A50 | B50: =历利表!B50 | C50: =C46-C49 | D50: =B50-C50 | E50: =历利表!C50 | F50: =F46-F49 | G50: =E50-F50 | H50: =历利表!D50 | I50: =I46-I49 | J50: =H50-I50 | K50: =历利表!E50 | L50: =L46-L49 | M50: =K50-L50
A52: 核对 | B52: =SUM(历利表!B6:'历利表'!B50)-SUM(B6:B50) | E52: =SUM(历利表!C6:'历利表'!C50)-SUM(E6:E50) | H52: =SUM(历利表!D6:'历利表'!D50)-SUM(H6:H50) | K52: =SUM(历利表!E6:'历利表'!E50)-SUM(K6:K50)

Sheet 评估结果汇总表
A1: 评估结果汇总表 | F1: =HYPERLINK("#目录1!A1","返回目录")
A2: 评估基准日：{{VALUATION_BASE_DATE}}
A3: ="被评估单位："&项目信息!B5&"" | E3: ="金额单位："&项目信息!B8&""
A4: 项目 | B4: 账面值 | C4: 评估值 | D4: 评估增减值 | E4: 增减值率(%)
A5: 流动资产 | B5: =历资表!E26
A6: 非流动资产 | B6: =历资表!E46
A7: 其中：可供出售金融资产 | B7: =历资表!E28
A8: 债权投资 | B8: =历资表!E29
A9: 其他债权投资 | B9: =历资表!E30
A10: 长期应收款 | B10: =历资表!E31
A11: 长期股权投资 | B11: =历资表!E32
A12: 其他权益工具投资 | B12: =历资表!E33
A13: 其他非流动金融资产 | B13: =历资表!E34
A14: 投资性房地产 | B14: =历资表!E35
A15: 固定资产净额 | B15: =历资表!E36
A16: 在建工程 | B16: =历资表!E37
A17: 工程物资 | B17: =历资表!E38
A18: 使用权资产 | B18: =历资表!E39
... A24: 其他非流动资产 | B24: =历资表!E45
A25: 资产总计 | B25: =B5+B6
A26: 流动负债 | B26: =历资表!E70
A27: 非流动负债 | B27: =历资表!E82
A28: 负债总计 | B28: =B27+B26
A29: 净资产（所有者权益） | B29: =历资表!E98
A30: 归属母公司所有者权益 | B30: =历资表!E96 | D30: =C30-B30 | E30: =D30/B30
A32: 核对 | B32: =B25-B28-B29

Sheet 净现金流计算表
A1: 净现金流计算表 | N1: =HYPERLINK("#目录1!A1","返回目录")
A2: 评估基准日：{{VALUATION_BASE_DATE}}
A3: ="被评估单位："&项目信息!B5&"" | M3: ="金额单位："&项目信息!B8&""
A4: 项目名称 | C4: 历史数据 | G4: 未来预测
C5: 2022年度 | D5: 2023年度 | E5: 2024年度 | F5: 2025年1-6月 | G5: 2025年7-12月 | H5: 2026年度 | I5: 2027年度 | J5: 2028年度 | K5: 2029年度 | L5: 2030年度 | M5: 永续年度
A6: 一、营业总收入 | C6: =SUM(C7) | D6: =SUM(D7) | E6: =SUM(E7) | F6: =SUM(F7) | G6: =SUM(G7) | H6: =SUM(H7) | I6: =SUM(I7) | J6: =SUM(J7) | ... M6: =SUM(M7)
A7: 其中：营业收入 | C7: =营业收入表!C17 | D7: =营业收入表!D17 | E7: =营业收入表!E17 | F7: =营业收入表!F17 | G7: =营业收入表!G17 | H7: =营业收入表!H17 | I7: =营业收入表!I17 | J7: =营业收入表!J17 | ... M7: =营业收入表!M17
A8: 二、营业总成本 | C8: =SUM(C9:C14) | D8: =SUM(D9:D14) | E8: =SUM(E9:E14) | F8: =SUM(F9:F14) | G8: =SUM(G9:G14) | H8: =SUM(H9:H14) | I8: =SUM(I9:I14) | J8: =SUM(J9:J14) | ... M8: =SUM(M9:M14)
A9: 其中：营业成本 | C9: =营业成本表!C17 | D9: =营业成本表!D17 | E9: =营业成本表!E17 | F9: =营业成本表!F17 | G9: =营业成本表!G17 | H9: =营业成本表!H17 | I9: =营业成本表!I17 | J9: =营业成本表!J17 | ... M9: =营业成本表!M17
A10: 税金及附加 | C10: =税金及附加表!C27 | D10: =税金及附加表!D27 | E10: =税金及附加表!E27 | F10: =税金及附加表!F27 | G10: =税金及附加表!G27 | H10: =税金及附加表!H27 | I10: =税金及附加表!I27 | J10: =税金及附加表!J27 | ... M10: =税金及附加表!M27
A11: 销售费用 | C11: =销售费用表!C62 | D11: =销售费用表!D62 | E11: =销售费用表!E62 | F11: =销售费用表!F62 | G11: =销售费用表!G62 | H11: =销售费用表!H62 | I11: =销售费用表!I62 | J11: =销售费用表!J62 | ... M11: =销售费用表!M62
A12: 管理费用 | C12: =管理费用表!C62 | D12: =管理费用表!D62 | E12: =管理费用表!E62 | F12: =管理费用表!F62 | G12: =管理费用表!G62 | H12: =管理费用表!H62 | I12: =管理费用表!I62 | J12: =管理费用表!J62 | ... M12: =管理费用表!M62
A13: 研发费用 | C13: =研发费用表!C63 | D13: =研发费用表!D63 | E13: =研发费用表!E63 | F13: =研发费用表!F63 | G13: =研发费用表!G63 | H13: =研发费用表!H63 | I13: =研发费用表!I63 | J13: =研发费用表!J63 | ... M13: =研发费用表!M63
A14: 财务费用 | C14: =财务费用表!C15 | D14: =财务费用表!D15 | E14: =财务费用表!E15 | F14: =财务费用表!F15 | G14: =财务费用表!G15 | H14: =财务费用表!H15 | I14: =财务费用表!I15 | J14: =财务费用表!J15 | ... M14: =财务费用表!M15
A15: 加：其他收益 | C15: =其他收益表!C9 | D15: =其他收益表!D9 | E15: =其他收益表!E9 | F15: =其他收益表!F9 | G15: =其他收益表!G9 | H15: =其他收益表!H9 | I15: =其他收益表!I9 | J15: =其他收益表!J9 | ... M15: =其他收益表!M9
A16: 投资收益（损失以“-”号填列） | C16: =投资收益表!C9 | D16: =投资收益表!D9 | E16: =投资收益表!E9 | F16: =投资收益表!F9 | G16: =投资收益表!G9 | H16: =投资收益表!H9 | I16: =投资收益表!I9 | J16: =投资收益表!J9 | ... M16: =投资收益表!M9
A17: 汇兑收益（损失以“-”号填列） | C17: =汇兑收益表!C9 | D17: =汇兑收益表!D9 | E17: =汇兑收益表!E9 | F17: =汇兑收益表!F9 | G17: =汇兑收益表!G9 | H17: =汇兑收益表!H9 | I17: =汇兑收益表!I9 | J17: =汇兑收益表!J9 | ... M17: =汇兑收益表!M9
A18: 净敞口套期收益（损失以“-”号填列） | C18: =净敞口套期收益表!C9 | D18: =净敞口套期收益表!D9 | E18: =净敞口套期收益表!E9 | F18: =净敞口套期收益表!F9 | G18: =净敞口套期收益表!G9 | H18: =净敞口套期收益表!H9 | I18: =净敞口套期收益表!I9 | J18: =净敞口套期收益表!J9 | ... M18: =净敞口套期收益表!M9
A19: 公允价值变动收益（损失以“-”号填列） | C19: =公允价值变动收益表!C9 | D19: =公允价值变动收益表!D9 | E19: =公允价值变动收益表!E9 | F19: =公允价值变动收益表!F9 | G19: =公允价值变动收益表!G9 | H19: =公允价值变动收益表!H9 | I19: =公允价值变动收益表!I9 | J19: =公允价值变动收益表!J9 | ... M19: =公允价值变动收益表!M9
A20: 信用减值损失（损失以“-”号填列） | C20: =-信用减值损失表!C9 | D20: =-信用减值损失表!D9 | E20: =-信用减值损失表!E9 | F20: =-信用减值损失表!F9 | G20: =-信用减值损失表!G9 | H20: =-信用减值损失表!H9 | I20: =-信用减值损失表!I9 | J20: =-信用减值损失表!J9 | ... M20: =-信用减值损失表!M9
A21: 资产减值损失（损失以“-”号填列） | C21: =-资产减值损失表!C9 | D21: =-资产减值损失表!D9 | E21: =-资产减值损失表!E9 | F21: =-资产减值损失表!F9 | G21: =-资产减值损失表!G9 | H21: =-资产减值损失表!H9 | I21: =-资产减值损失表!I9 | J21: =-资产减值损失表!J9 | ... M21: =-资产减值损失表!M9
A22: 资产处置收益（损失以“-”号填列） | C22: =资产处置收益表!C9 | D22: =资产处置收益表!D9 | E22: =资产处置收益表!E9 | F22: =资产处置收益表!F9 | G22: =资产处置收益表!G9 | H22: =资产处置收益表!H9 | I22: =资产处置收益表!I9 | J22: =资产处置收益表!J9 | ... M22: =资产处置收益表!M9
A23: 三、营业利润（亏损以“-”号填列） | C23: =C6-C8+SUM(C15:C16,C17:C22) | D23: =D6-D8+SUM(D15:D16,D17:D22) | E23: =E6-E8+SUM(E15:E16,E17:E22) | F23: =F6-F8+SUM(F15:F16,F17:F22) | G23: =G6-G8+SUM(G15:G16,G17:G22) | H23: =H6-H8+SUM(H15:H16,H17:H22) | I23: =I6-I8+SUM(I15:I16,I17:I22) | J23: =J6-J8+SUM(J15:J16,J17:J22) | ... M23: =M6-M8+SUM(M15:M16,M17:M22)
A24: 加：营业外收入 | C24: =营业外收入表!C9 | D24: =营业外收入表!D9 | E24: =营业外收入表!E9 | F24: =营业外收入表!F9 | G24: =营业外收入表!G9 | H24: =营业外收入表!H9 | I24: =营业外收入表!I9 | J24: =营业外收入表!J9 | ... M24: =营业外收入表!M9
A25: 减：营业外支出 | C25: =营业外支出表!C9 | D25: =营业外支出表!D9 | E25: =营业外支出表!E9 | F25: =营业外支出表!F9 | G25: =营业外支出表!G9 | H25: =营业外支出表!H9 | I25: =营业外支出表!I9 | J25: =营业外支出表!J9 | ... M25: =营业外支出表!M9
A26: 四、利润总额（亏损总额以“-”号填列） | C26: =C23+C24-C25 | D26: =D23+D24-D25 | E26: =E23+E24-E25 | F26: =F23+F24-F25 | G26: =G23+G24-G25 | H26: =H23+H24-H25 | I26: =I23+I24-I25 | J26: =J23+J24-J25 | ... M26: =M23+M24-M25
A27: 减：所得税费用 | C27: =所得税表!C43 | D27: =所得税表!D43 | E27: =所得税表!E43 | F27: =所得税表!F43 | G27: =所得税表!G43 | H27: =所得税表!H43 | I27: =所得税表!I43 | J27: =所得税表!J43 | ... M27: =所得税表!M43
A28: 五、净利润（净亏损以“-”号填列） | C28: =C26-C27 | D28: =D26-D27 | E28: =E26-E27 | F28: =F26-F27 | G28: =G26-G27 | H28: =H26-H27 | I28: =I26-I27 | J28: =J26-J27 | ... M28: =M26-M27
A29: 1．归属于母公司股东的净利润（净亏损以“-”号填列） | C29: =C28-C30 | D29: =D28-D30 | E29: =E28-E30 | F29: =F28-F30 | G29: =G28-G30 | H29: =H28-H30 | I29: =I28-I30 | J29: =J28-J30 | ... M29: =M28-M30
A30: 2．少数股东损益（净亏损以“-”号填列）
A31: 加：折旧与摊销 | C31: =折旧摊销、资本性支出表!C19 | D31: =折旧摊销、资本性支出表!D19 | E31: =折旧摊销、资本性支出表!E19 | F31: =折旧摊销、资本性支出表!F19 | G31: =折旧摊销、资本性支出表!G19 | H31: =折旧摊销、资本性支出表!H19 | I31: =折旧摊销、资本性支出表!I19 | J31: =折旧摊销、资本性支出表!J19 | ... M31: =折旧摊销、资本性支出表!M19
A32: 经营现金流 | C32: =SUM(C29+C31) | D32: =SUM(D29+D31) | E32: =SUM(E29+E31) | F32: =SUM(F29+F31) | G32: =SUM(G29+G31) | H32: =SUM(H29+H31) | I32: =SUM(I29+I31) | J32: =SUM(J29+J31) | ... M32: =SUM(M29+M31)
A33: 加：税后付息债务利息 | C33: =(财务费用表!C6+财务费用表!C11)*(1-所得税表!C42) | D33: =(财务费用表!D6+财务费用表!D11)*(1-所得税表!D42) | E33: =(财务费用表!E6+财务费用表!E11)*(1-所得税表!E42) | F33: =(财务费用表!F6+财务费用表!F11)*(1-所得税表!F42) | G33: =(财务费用表!G6+财务费用表!G11)*(1-所得税表!G42) | H33: =(财务费用表!H6+财务费用表!H11)*(1-所得税表!H42) | I33: =(财务费用表!I6+财务费用表!I11)*(1-所得税表!I42) | J33: =(财务费用表!J6+财务费用表!J11)*(1-所得税表!J42) | ... M33: =(财务费用表!M6+财务费用表!M11)*(1-所得税表!M42)
A34: 减：资本性支出 | C34: =折旧摊销、资本性支出表!C29 | D34: =折旧摊销、资本性支出表!D29 | E34: =折旧摊销、资本性支出表!E29 | F34: =折旧摊销、资本性支出表!F29 | G34: =折旧摊销、资本性支出表!G29 | H34: =折旧摊销、资本性支出表!H29 | I34: =折旧摊销、资本性支出表!I29 | J34: =折旧摊销、资本性支出表!J29 | ... M34: =折旧摊销、资本性支出表!M29
A35: 减：营运资金增加（减少） | C35: =营运资金表!C76 | D35: =营运资金表!D76 | E35: =营运资金表!E76 | F35: =营运资金表!F76 | G35: =营运资金表!G78 | H35: =营运资金表!H78 | I35: =营运资金表!I78 | J35: =营运资金表!J78 | K35: =营运资金表!K78 | L35: =营运资金表!L78 | M35: =营运资金表!M76
A36: 净现金流 | C36: =C32+C33-C34-C35 | D36: =D32+D33-D34-D35 | E36: =E32+E33-E34-E35 | F36: =F32+F33-F34-F35 | G36: =G32+G33-G34-G35 | H36: =H32+H33-H34-H35 | I36: =I32+I33-I34-I35 | J36: =J32+J33-J34-J35 | ... M36: =M32+M33-M34-M35
A37: 折现年限 | G37: 0.2500 | H37: 1.0000 | I37: 2.0000 | J37: 3.0000 | K37: 4.0000 | L37: 5.0000
A38: 折现系数 | G38: =ROUND(1/(1+折现率计算表!C24)^G37,4) | H38: =ROUND(1/(1+折现率计算表!C24)^H37,4) | I38: =ROUND(1/(1+折现率计算表!C24)^I37,4) | J38: =ROUND(1/(1+折现率计算表!C24)^J37,4) | K38: =ROUND(1/(1+折现率计算表!C24)^K37,4) | L38: =ROUND(1/(1+折现率计算表!C24)^L37,4) | M38: =ROUND(L38/折现率计算表!C24,4)
A39: 净现金流量现值 | G39: =ROUND(G36*G38,2) | H39: =ROUND(H36*H38,2) | I39: =ROUND(I36*I38,2) | J39: =ROUND(J36*J38,2) | K39: =ROUND(K36*K38,2) | L39: =ROUND(L36*L38,2) | M39: =ROUND(M36*M38,2)
A40: 经营性资产现值之和 | G40: =ROUND(SUM(G39:M39),2)
...

Sheet 主要产品及服务
A1: 主要产品及服务 | H1: =HYPERLINK("#目录1!A1","返回目录")
A2: 评估基准日：{{VALUATION_BASE_DATE}}
A3: ="被评估单位："&项目信息!B5&"" | G3: ="金额单位："&项目信息!B8&""
A4: 板块 | B4: 序号 | C4: 产品或服务名称 | D4: 增值税率（%） | E4: 营业收入预测方式 | F4: 营业成本预测方式 | G4: 备注

Sheet 营业收入表
A1: 营业收入分析预测表 | N1: =HYPERLINK("#目录1!A1","返回目录")
A2: 评估基准日：{{VALUATION_BASE_DATE}}
A3: ="被评估单位："&项目信息!B5&"" | M3: ="金额单位："&项目信息!B8&""
A4: 产品/服务名称 | C4: 历史数据 | G4: 未来预测
C5: 2022年度 | D5: 2023年度 | E5: 2024年度 | F5: 2025年1-6月 | G5: 2025年7-12月 | H5: 2026年度 | I5: 2027年度 | J5: 2028年度 | K5: 2029年度 | L5: 2030年度 | M5: 永续年度
A6: 主营业务收入：
C7: =营业收入附表!C9 | D7: =营业收入附表!D9 | E7: =营业收入附表!E9 | F7: =营业收入附表!F9 | G7: =营业收入附表!G9 | H7: =营业收入附表!H9 | I7: =营业收入附表!I9 | J7: =营业收入附表!J9 | ... M7: =营业收入附表!M9
A8: 其他 | C8: =营业收入附表!C12 | D8: =营业收入附表!D12 | E8: =营业收入附表!E12 | F8: =营业收入附表!F12 | G8: =营业收入附表!G12 | H8: =营业收入附表!H12 | I8: =营业收入附表!I12 | J8: =营业收入附表!J12 | ... M8: =营业收入附表!M12
A11: 主营业务收入小计 | C11: =SUM(C6:C10) | D11: =SUM(D6:D10) | E11: =SUM(E6:E10) | F11: =SUM(F6:F10) | G11: =SUM(G6:G10) | H11: =SUM(H6:H10) | I11: =SUM(I6:I10) | J11: =SUM(J6:J10) | ... M11: =SUM(M6:M10)
A12: 其他业务收入：
A13: 其他 | C13: =营业收入附表!C19 | D13: =营业收入附表!D19 | E13: =营业收入附表!E19 | F13: =营业收入附表!F19 | G13: =营业收入附表!G19 | H13: =营业收入附表!H19 | I13: =营业收入附表!I19 | J13: =营业收入附表!J19 | ... M13: =营业收入附表!M19
A16: 其他业务收入小计 | C16: =SUM(C12:C15) | D16: =SUM(D12:D15) | E16: =SUM(E12:E15) | F16: =SUM(F12:F15) | G16: =SUM(G12:G15) | H16: =SUM(H12:H15) | I16: =SUM(I12:I15) | J16: =SUM(J12:J15) | ... M16: =SUM(M12:M15)
A17: 营业收入合计 | C17: =C11+C16 | D17: =D11+D16 | E17: =E11+E16 | F17: =F11+F16 | G17: =G11+G16 | H17: =H11+H16 | I17: =I11+I16 | J17: =J11+J16 | ... M17: =M11+M16
A19: 主营业务收入 | C19: 增长率（%） | D19: =ROUND((D11-C11)/C11,4) | E19: =ROUND((E11-D11)/D11,4) | F19: =ROUND((F11/6*12-E11)/E11,4) | G19: =ROUND((G11+F11-E11)/E11,4) | H19: =ROUND((H11-(G11+F11))/(G11+F11),4) | I19: =ROUND((I11-H11)/H11,4) | J19: =ROUND((J11-I11)/I11,4) | K19: =ROUND((K11-J11)/J11,4) | L19: =ROUND((L11-K11)/K11,4) | M19: =ROUND((M11-L11)/L11,4)
C20: 复合增长率（%） | F20: =ROUND(((F11/6*12)/C11)^(1/3),4)-1 | L20: =ROUND((L11/(G11+F11))^(1/5),4)-1
A21: 其他业务收入 | C21: 增长率（%） | D21: =ROUND((D16-C16)/C16,4) | E21: =ROUND((E16-D16)/D16,4) | F21: =ROUND((F16/6*12-E16)/E16,4) | G21: =ROUND((G16+F16-E16)/E16,4) | H21: =ROUND((H16-(G16+F16))/(G16+F16),4) | I21: =ROUND((I16-H16)/H16,4) | J21: =ROUND((J16-I16)/I16,4) | K21: =ROUND((K16-J16)/J16,4) | L21: =ROUND((L16-K16)/K16,4) | M21: =ROUND((M16-L16)/L16,4)
C22: 复合增长率（%） | F22: =ROUND(((F16/6*12)/C16)^(1/3),4)-1 | L22: =ROUND((L16/(G16+F16))^(1/5),4)-1
A23: 营业收入 | C23: 增长率（%） | D23: =ROUND((D17-C17)/C17,4) | E23: =ROUND((E17-D17)/D17,4) | F23: =ROUND((F17/6*12-E17)/E17,4) | G23: =ROUND((G17+F17-E17)/E17,4) | H23: =ROUND((H17-(G17+F17))/(G17+F17),4) | I23: =ROUND((I17-H17)/H17,4) | J23: =ROUND((J17-I17)/I17,4) | K23: =ROUND((K17-J17)/J17,4) | L23: =ROUND((L17-K17)/K17,4) | M23: =ROUND((M17-L17)/L17,4)
C24: 复合增长率（%） | F24: =ROUND(((F17/6*12)/C17)^(1/3),4)-1 | L24: =ROUND((L17/(G17+F17))^(1/5),4)-1
A25: 核对 | C25: =C17-营业收入附表!C23 | D25: =D17-营业收入附表!D23 | E25: =E17-营业收入附表!E23 | F25: =F17-营业收入附表!F23 | G25: =G17-营业收入附表!G23 | H25: =H17-营业收入附表!H23 | I25: =I17-营业收入附表!I23 | J25: =J17-营业收入附表!J23 | ... M25: =M17-营业收入附表!M23

Sheet 营业收入附表
A1: 营业收入分析预测表 | N1: =HYPERLINK("#目录1!A1","返回目录")
A2: 评估基准日：{{VALUATION_BASE_DATE}}
A3: ="被评估单位："&项目信息!B5&"" | M3: ="金额单位："&项目信息!B8&""
A4: 产品/服务名称 | B4: 项目 | C4: 历史数据 | G4: 未来预测
C5: 2022年度 | D5: 2023年度 | E5: 2024年度 | F5: 2025年1-6月 | G5: 2025年7-12月 | H5: 2026年度 | I5: 2027年度 | J5: 2028年度 | K5: 2029年度 | L5: 2030年度 | M5: 永续年度
A6: 主营业务收入：
B7: 数量
B8: 单价 | C8: =ROUND(C9/C7,2) | D8: =ROUND(D9/D7,2) | E8: =ROUND(E9/E7,2) | F8: =ROUND(F9/F7,2) | M8: =L8
B9: 收入 | G9: =ROUND(G7*G8,2) | H9: =ROUND(H7*H8,2) | I9: =ROUND(I7*I8,2) | J9: =ROUND(J7*J8,2) | K9: =ROUND(K7*K8,2) | L9: =ROUND(L7*L8,2) | M9: =ROUND(M7*M8,2)
A10: 其他 | B10: 数量
B11: 单价 | C11: =ROUND(C12/C10,2) | D11: =ROUND(D12/D10,2) | E11: =ROUND(E12/E10,2) | F11: =ROUND(F12/F10,2)
B12: 收入 | G12: =ROUND(G10*G11,2) | H12: =ROUND(H10*H11,2) | I12: =ROUND(I10*I11,2) | J12: =ROUND(J10*J11,2) | K12: =ROUND(K10*K11,2) | L12: =ROUND(L10*L11,2) | M12: =ROUND(M10*M11,2)
A15: 主营业务收入小计 | C15: =SUMIF($B7:$B14,"收入",C7:C14) | D15: =SUMIF($B7:$B14,"收入",D7:D14) | E15: =SUMIF($B7:$B14,"收入",E7:E14) | F15: =SUMIF($B7:$B14,"收入",F7:F14) | G15: =SUMIF($B7:$B14,"收入",G7:G14) | H15: =SUMIF($B7:$B14,"收入",H7:H14) | I15: =SUMIF($B7:$B14,"收入",I7:I14) | J15: =SUMIF($B7:$B14,"收入",J7:J14) | ... M15: =SUMIF($B7:$B14,"收入",M7:M14)
A16: 其他业务收入：
A17: 其他 | B17: 数量
B18: 单价 | C18: =ROUND(C19/C17,2) | D18: =ROUND(D19/D17,2) | E18: =ROUND(E19/E17,2) | F18: =ROUND(F19/F17,2)
B19: 收入 | G19: =ROUND(G17*G18,2) | H19: =ROUND(H17*H18,2) | I19: =ROUND(I17*I18,2) | J19: =ROUND(J17*J18,2) | K19: =ROUND(K17*K18,2) | L19: =ROUND(L17*L18,2) | M19: =ROUND(M17*M18,2)
A22: 其他业务收入小计 | C22: =SUMIF($B17:$B21,"收入",C17:C21) | D22: =SUMIF($B17:$B21,"收入",D17:D21) | E22: =SUMIF($B17:$B21,"收入",E17:E21) | F22: =SUMIF($B17:$B21,"收入",F17:F21) | G22: =SUMIF($B17:$B21,"收入",G17:G21) | H22: =SUMIF($B17:$B21,"收入",H17:H21) | I22: =SUMIF($B17:$B21,"收入",I17:I21) | J22: =SUMIF($B17:$B21,"收入",J17:J21) | ... M22: =SUMIF($B17:$B21,"收入",M17:M21)
A23: 营业收入合计 | C23: =C15+C22 | D23: =D15+D22 | E23: =E15+E22 | F23: =F15+F22 | G23: =G15+G22 | H23: =H15+H22 | I23: =I15+I22 | J23: =J15+J22 | ... M23: =M15+M22
A25: 【HD】主营业务收入核对 | C25: =C15-历利调整后表!D8 | D25: =D15-历利调整后表!G8 | E25: =E15-历利调整后表!J8 | F25: =F15-历利调整后表!M8
A26: 【HD】其他业务收入核对 | C26: =C22-历利调整后表!D9 | D26: =D22-历利调整后表!G9 | E26: =E22-历利调整后表!J9 | F26: =F22-历利调整后表!M9
A27: 【HD】营业收入核对 | C27: =C23-历利调整后表!D7 | D27: =D23-历利调整后表!G7 | E27: =E23-历利调整后表!J7 | F27: =F23-历利调整后表!M7

Sheet 营业成本表
A1: 营业成本分析预测表 | N1: =HYPERLINK("#目录1!A1","返回目录")
A2: 评估基准日：{{VALUATION_BASE_DATE}}
A3: ="被评估单位："&项目信息!B5&"" | M3: ="金额单位："&项目信息!B8&""
A4: 产品/服务名称 | C4: 历史数据 | G4: 未来预测
C5: 2022年度 | D5: 2023年度 | E5: 2024年度 | F5: 2025年1-6月 | G5: 2025年7-12月 | H5: 2026年度 | I5: 2027年度 | J5: 2028年度 | K5: 2029年度 | L5: 2030年度 | M5: 永续年度
A6: 主营业务成本：
C7: =营业成本附表!C17 | D7: =营业成本附表!D17 | E7: =营业成本附表!E17 | F7: =营业成本附表!F17 | G7: =营业成本附表!G17 | H7: =营业成本附表!H17 | I7: =营业成本附表!I17 | J7: =营业成本附表!J17 | ... M7: =营业成本附表!M17
A8: 其他 | C8: =营业成本附表!C20 | D8: =营业成本附表!D20 | E8: =营业成本附表!E20 | F8: =营业成本附表!F20 | G8: =营业成本附表!G20 | H8: =营业成本附表!H20 | I8: =营业成本附表!I20 | J8: =营业成本附表!J20 | ... M8: =营业成本附表!M20
A11: 主营业务成本小计 | C11: =SUM(C7:C10) | D11: =SUM(D7:D10) | E11: =SUM(E7:E10) | F11: =SUM(F7:F10) | G11: =SUM(G7:G10) | H11: =SUM(H7:H10) | I11: =SUM(I7:I10) | J11: =SUM(J7:J10) | ... M11: =SUM(M7:M10)
A12: 其他业务成本：
A13: 其他 | C13: =营业成本附表!C27 | D13: =营业成本附表!D27 | E13: =营业成本附表!E27 | F13: =营业成本附表!F27 | G13: =营业成本附表!G27 | H13: =营业成本附表!H27 | I13: =营业成本附表!I27 | J13: =营业成本附表!J27 | ... M13: =营业成本附表!M27
A16: 其他业务成本小计 | C16: =SUM(C13:C15) | D16: =SUM(D13:D15) | E16: =SUM(E13:E15) | F16: =SUM(F13:F15) | G16: =SUM(G13:G15) | H16: =SUM(H13:H15) | I16: =SUM(I13:I15) | J16: =SUM(J13:J15) | ... M16: =SUM(M13:M15)
A17: 营业成本合计 | C17: =C11+C16 | D17: =D11+D16 | E17: =E11+E16 | F17: =F11+F16 | G17: =G11+G16 | H17: =H11+H16 | I17: =I11+I16 | J17: =J11+J16 | ... M17: =M11+M16
A19: 主营业务成本 | C19: 增长率（%） | D19: =ROUND((D11-C11)/C11,4) | E19: =ROUND((E11-D11)/D11,4) | F19: =ROUND((F11/6*12-E11)/E11,4) | G19: =ROUND((G11+F11-E11)/E11,4) | H19: =ROUND((H11-(G11+F11))/(G11+F11),4) | I19: =ROUND((I11-H11)/H11,4) | J19: =ROUND((J11-I11)/I11,4) | K19: =ROUND((K11-J11)/J11,4) | L19: =ROUND((L11-K11)/K11,4) | M19: =ROUND((M11-L11)/L11,4)
C20: 复合增长率（%） | F20: =ROUND(((F11/6*12)/C11)^(1/3),4)-1 | L20: =ROUND((L11/(G11+F11))^(1/5),4)-1
A21: 其他业务成本 | C21: 增长率（%） | D21: =ROUND((D16-C16)/C16,4) | E21: =ROUND((E16-D16)/D16,4) | F21: =ROUND((F16/6*12-E16)/E16,4) | G21: =ROUND((G16+F16-E16)/E16,4) | H21: =ROUND((H16-(G16+F16))/(G16+F16),4) | I21: =ROUND((I16-H16)/H16,4) | J21: =ROUND((J16-I16)/I16,4) | K21: =ROUND((K16-J16)/J16,4) | L21: =ROUND((L16-K16)/K16,4) | M21: =ROUND((M16-L16)/L16,4)
C22: 复合增长率（%） | F22: =ROUND(((F16/6*12)/C16)^(1/3),4)-1 | L22: =ROUND((L16/(G16+F16))^(1/5),4)-1
A23: 营业成本 | C23: 增长率（%） | D23: =ROUND((D17-C17)/C17,4) | E23: =ROUND((E17-D17)/D17,4) | F23: =ROUND((F17/6*12-E17)/E17,4) | G23: =ROUND((G17+F17-E17)/E17,4) | H23: =ROUND((H17-(G17+F17))/(G17+F17),4) | I23: =ROUND((I17-H17)/H17,4) | J23: =ROUND((J17-I17)/I17,4) | K23: =ROUND((K17-J17)/J17,4) | L23: =ROUND((L17-K17)/K17,4) | M23: =ROUND((M17-L17)/L17,4)
C24: 复合增长率（%） | F24: =ROUND(((F17/6*12)/C17)^(1/3),4)-1 | L24: =ROUND((L17/(G17+F17))^(1/5),4)-1
A25: 主营业务毛利率 | C25: =ROUND((1-C11/营业收入表!C11),4) | D25: =ROUND((1-D11/营业收入表!D11),4) | E25: =ROUND((1-E11/营业收入表!E11),4) | F25: =ROUND((1-F11/营业收入表!F11),4) | G25: =ROUND((1-G11/营业收入表!G11),4) | H25: =ROUND((1-H11/营业收入表!H11),4) | I25: =ROUND((1-I11/营业收入表!I11),4) | J25: =ROUND((1-J11/营业收入表!J11),4) | ... M25: =ROUND((1-M11/营业收入表!M11),4)
A26: 其他业务毛利率 | C26: =ROUND((1-C16/营业收入表!C16),4) | D26: =ROUND((1-D16/营业收入表!D16),4) | E26: =ROUND((1-E16/营业收入表!E16),4) | F26: =ROUND((1-F16/营业收入表!F16),4) | G26: =ROUND((1-G16/营业收入表!G16),4) | H26: =ROUND((1-H16/营业收入表!H16),4) | I26: =ROUND((1-I16/营业收入表!I16),4) | J26: =ROUND((1-J16/营业收入表!J16),4) | ... M26: =ROUND((1-M16/营业收入表!M16),4)
A27: 核对 | C27: =C17-营业成本附表!C31 | D27: =D17-营业成本附表!D31 | E27: =E17-营业成本附表!E31 | F27: =F17-营业成本附表!F31 | G27: =G17-营业成本附表!G31 | H27: =H17-营业成本附表!H31 | I27: =I17-营业成本附表!I31 | J27: =J17-营业成本附表!J31 | ... M27: =M17-营业成本附表!M31

Sheet 营业成本附表
A1: 营业成本分析预测表 | N1: =HYPERLINK("#目录1!A1","返回目录")
A2: 评估基准日：{{VALUATION_BASE_DATE}}
A3: ="被评估单位："&项目信息!B5&"" | M3: ="金额单位："&项目信息!B8&""
A4: 产品/服务名称 | B4: 项目 | C4: 历史数据 | G4: 未来预测
C5: 2022年度 | D5: 2023年度 | E5: 2024年度 | F5: 2025年1-6月 | G5: 2025年7-12月 | H5: 2026年度 | I5: 2027年度 | J5: 2028年度 | K5: 2029年度 | L5: 2030年度 | M5: 永续年度
A6: 主营业务成本：
B7: 材料 | M7: =L7
B8: 人工 | M8: =L8
B9: 制造费用 | M9: =L9
B10: 折旧 | M10: =L10
B11: 摊销
B17: 成本 | C17: =SUM(C7:C16) | D17: =SUM(D7:D16) | E17: =SUM(E7:E16) | F17: =SUM(F7:F16) | G17: =SUM(G7:G16) | H17: =SUM(H7:H16) | I17: =SUM(I7:I16) | J17: =SUM(J7:J16) | ... M17: =SUM(M7:M16)
A18: 其他 | B18: 数量 | C18: =营业收入附表!C10 | D18: =营业收入附表!D10 | E18: =营业收入附表!E10 | F18: =营业收入附表!F10 | G18: =营业收入附表!G10 | H18: =营业收入附表!H10 | I18: =营业收入附表!I10 | J18: =营业收入附表!J10 | ... M18: =营业收入附表!M10
B19: 单价 | C19: =ROUND(C20/C18,2) | D19: =ROUND(D20/D18,2) | E19: =ROUND(E20/E18,2) | F19: =ROUND(F20/F18,2)
B20: 成本 | G20: =ROUND(G18*G19,2) | H20: =ROUND(H18*H19,2) | I20: =ROUND(I18*I19,2) | J20: =ROUND(J18*J19,2) | K20: =ROUND(K18*K19,2) | L20: =ROUND(L18*L19,2) | M20: =ROUND(M18*M19,2)
A23: 主营业务成本小计 | C23: =SUMIF($B7:$B22,"成本",C7:C22) | D23: =SUMIF($B7:$B22,"成本",D7:D22) | E23: =SUMIF($B7:$B22,"成本",E7:E22) | F23: =SUMIF($B7:$B22,"成本",F7:F22) | G23: =SUMIF($B7:$B22,"成本",G7:G22) | H23: =SUMIF($B7:$B22,"成本",H7:H22) | I23: =SUMIF($B7:$B22,"成本",I7:I22) | J23: =SUMIF($B7:$B22,"成本",J7:J22) | ... M23: =SUMIF($B7:$B22,"成本",M7:M22)
A24: 其他业务成本：
A25: 其他 | B25: 数量 | C25: =营业收入附表!C17 | D25: =营业收入附表!D17 | E25: =营业收入附表!E17 | F25: =营业收入附表!F17 | G25: =营业收入附表!G17 | H25: =营业收入附表!H17 | I25: =营业收入附表!I17 | J25: =营业收入附表!J17 | ... M25: =营业收入附表!M17
B26: 单价 | C26: =ROUND(C27/C25,2) | D26: =ROUND(D27/D25,2) | E26: =ROUND(E27/E25,2) | F26: =ROUND(F27/F25,2)
B27: 成本 | G27: =ROUND(G25*G26,2) | H27: =ROUND(H25*H26,2) | I27: =ROUND(I25*I26,2) | J27: =ROUND(J25*J26,2) | K27: =ROUND(K25*K26,2) | L27: =ROUND(L25*L26,2) | M27: =ROUND(M25*M26,2)
A30: 其他业务成本小计 | C30: =SUMIF($B25:$B29,"成本",C25:C29) | D30: =SUMIF($B25:$B29,"成本",D25:D29) | E30: =SUMIF($B25:$B29,"成本",E25:E29) | F30: =SUMIF($B25:$B29,"成本",F25:F29) | G30: =SUMIF($B25:$B29,"成本",G25:G29) | H30: =SUMIF($B25:$B29,"成本",H25:H29) | I30: =SUMIF($B25:$B29,"成本",I25:I29) | J30: =SUMIF($B25:$B29,"成本",J25:J29) | ... M30: =SUMIF($B25:$B29,"成本",M25:M29)
A31: 营业成本合计 | C31: =C23+C30 | D31: =D23+D30 | E31: =E23+E30 | F31: =F23+F30 | G31: =G23+G30 | H31: =H23+H30 | I31: =I23+I30 | J31: =J23+J30 | ... M31: =M23+M30
A33: 【HD】主营业务成本核对 | C33: =C23-历利调整后表!D15 | D33: =D23-历利调整后表!G15 | E33: =E23-历利调整后表!J15 | F33: =F23-历利调整后表!M15
A34: 【HD】其他业务成本核对 | C34: =C30-历利调整后表!D16 | D34: =D30-历利调整后表!G16 | E34: =E30-历利调整后表!J16 | F34: =F30-历利调整后表!M16
A35: 【HD】营业成本核对 | C35: =C31-历利调整后表!D14 | D35: =D31-历利调整后表!G14 | E35: =E31-历利调整后表!J14 | F35: =F31-历利调整后表!M14
A36: 制造费用核对 | C36: =SUMIF(B7:B29,"制造费用",C7:C29)-制造费用表!C62 | D36: =SUMIF(B7:B29,"制造费用",D7:D29)-制造费用表!D62 | E36: =SUMIF(B7:B29,"制造费用",E7:E29)-制造费用表!E62 | F36: =SUMIF(B7:B29,"制造费用",F7:F29)-制造费用表!F62 | G36: =SUMIF(B7:B29,"制造费用",G7:G29)-制造费用表!G62 | H36: =SUMIF(B7:B29,"制造费用",H7:H29)-制造费用表!H62 | I36: =SUMIF(B7:B29,"制造费用",I7:I29)-制造费用表!I62 | J36: =SUMIF(B7:B29,"制造费用",J7:J29)-制造费用表!J62 | K36: =SUMIF(B7:B29,"制造费用",K7:K29)-制造费用表!K62 | L36: =SUMIF(B7:B29,"制造费用",L7:L29)-制造费用表!L62 | M36: =SUMIF(B7:B29,"制造费用",M7:M29)-制造费用表!M62
A37: 人工核对 | C37: =SUMIF(B7:B29,"人工",C7:C29)-人工成本表!C27 | D37: =SUMIF(B7:B29,"人工",D7:D29)-人工成本表!D27 | E37: =SUMIF(B7:B29,"人工",E7:E29)-人工成本表!E27 | F37: =SUMIF(B7:B29,"人工",F7:F29)-人工成本表!F27 | G37: =SUMIF(B7:B29,"人工",G7:G29)-人工成本表!G27 | H37: =SUMIF(B7:B29,"人工",H7:H29)-人工成本表!H27 | I37: =SUMIF(B7:B29,"人工",I7:I29)-人工成本表!I27 | J37: =SUMIF(B7:B29,"人工",J7:J29)-人工成本表!J27 | K37: =SUMIF(B7:B29,"人工",K7:K29)-人工成本表!K27 | L37: =SUMIF(B7:B29,"人工",L7:L29)-人工成本表!L27 | M37: =SUMIF(B7:B29,"人工",M7:M29)-人工成本表!M27
A38: 折旧核对 | C38: =SUMIF(B7:B29,"折旧",C7:C29)-折旧摊销、资本性支出表!C7 | D38: =SUMIF(B7:B29,"折旧",D7:D29)-折旧摊销、资本性支出表!D7 | E38: =SUMIF(B7:B29,"折旧",E7:E29)-折旧摊销、资本性支出表!E7 | F38: =SUMIF(B7:B29,"折旧",F7:F29)-折旧摊销、资本性支出表!F7 | G38: =SUMIF(B7:B29,"折旧",G7:G29)-折旧摊销、资本性支出表!G7 | H38: =SUMIF(B7:B29,"折旧",H7:H29)-折旧摊销、资本性支出表!H7 | I38: =SUMIF(B7:B29,"折旧",I7:I29)-折旧摊销、资本性支出表!I7 | J38: =SUMIF(B7:B29,"折旧",J7:J29)-折旧摊销、资本性支出表!J7 | K38: =SUMIF(B7:B29,"折旧",K7:K29)-折旧摊销、资本性支出表!K7 | L38: =SUMIF(B7:B29,"折旧",L7:L29)-折旧摊销、资本性支出表!L7 | M38: =SUMIF(B7:B29,"折旧",M7:M29)-折旧摊销、资本性支出表!M7
A39: 摊销核对 | C39: =SUMIF(B7:B29,"摊销",C7:C29)-折旧摊销、资本性支出表!C8 | D39: =SUMIF(B7:B29,"摊销",D7:D29)-折旧摊销、资本性支出表!D8 | E39: =SUMIF(B7:B29,"摊销",E7:E29)-折旧摊销、资本性支出表!E8 | F39: =SUMIF(B7:B29,"摊销",F7:F29)-折旧摊销、资本性支出表!F8 | G39: =SUMIF(B7:B29,"摊销",G7:G29)-折旧摊销、资本性支出表!G8 | H39: =SUMIF(B7:B29,"摊销",H7:H29)-折旧摊销、资本性支出表!H8 | I39: =SUMIF(B7:B29,"摊销",I7:I29)-折旧摊销、资本性支出表!I8 | J39: =SUMIF(B7:B29,"摊销",J7:J29)-折旧摊销、资本性支出表!J8 | K39: =SUMIF(B7:B29,"摊销",K7:K29)-折旧摊销、资本性支出表!K8 | L39: =SUMIF(B7:B29,"摊销",L7:L29)-折旧摊销、资本性支出表!L8 | M39: =SUMIF(B7:B29,"摊销",M7:M29)-折旧摊销、资本性支出表!M8

Sheet 人工成本表
A1: 人工及工资预测表 | N1: =HYPERLINK("#目录1!A1","返回目录")
A2: 评估基准日：{{VALUATION_BASE_DATE}}
A3: ="被评估单位："&项目信息!B5&"" | M3: ="金额单位："&项目信息!B8&""
A4: 一、人员数量
A5: 人员类别 | B5: 核算科目 | C5: 历史数据 | G5: 未来预测
C6: 2022年度 | D6: 2023年度 | E6: 2024年度 | F6: 2025年1-6月 | G6: 2025年7-12月 | H6: 2026年度 | I6: 2027年度 | J6: 2028年度 | K6: 2029年度 | L6: 2030年度 | M6: 永续年度
A7: 生产人员 | B7: 营业成本 | H7: =G7 | I7: =H7 | J7: =I7 | K7: =J7 | L7: =K7 | M7: =L7
A8: 制造人员 | B8: 制造费用
A9: 销售人员 | B9: 销售费用
A10: 管理人员及其他人员 | B10: 管理费用
A11: 研发人员 | B11: 研发费用
A12: 员工人数合计 | C12: =SUM(C7:C11) | D12: =SUM(D7:D11) | E12: =SUM(E7:E11) | F12: =SUM(F7:F11) | G12: =SUM(G7:G11) | H12: =SUM(H7:H11) | I12: =SUM(I7:I11) | J12: =SUM(J7:J11) | ... M12: =SUM(M7:M11)
A14: 二、平均工资
A15: 人员类别 | B15: 核算科目 | C15: 历史数据 | G15: 未来预测
C16: 2022年度 | D16: 2023年度 | E16: 2024年度 | F16: 2025年1-6月 | G16: 2025年7-12月 | H16: 2026年度 | I16: 2027年度 | J16: 2028年度 | K16: 2029年度 | L16: 2030年度 | M16: 永续年度
A17: 生产人员 | B17: 营业成本 | C17: =ROUND((C27/C7),2) | D17: =ROUND((D27/D7),2) | E17: =ROUND((E27/E7),2) | F17: =ROUND((F27/F7),2) | M17: =L17
A18: 制造人员 | B18: 制造费用 | C18: =ROUND((C28/C8),2) | D18: =ROUND((D28/D8),2) | E18: =ROUND((E28/E8),2) | F18: =ROUND((F28/F8),2)
A19: 销售人员 | B19: 销售费用 | C19: =ROUND((C29/C9),2) | D19: =ROUND((D29/D9),2) | E19: =ROUND((E29/E9),2) | F19: =ROUND((F29/F9),2)
A20: 管理人员及其他人员 | B20: 管理费用 | C20: =ROUND((C30/C10),2) | D20: =ROUND((D30/D10),2) | E20: =ROUND((E30/E10),2) | F20: =ROUND((F30/F10),2)
A21: 研发人员 | B21: 研发费用 | C21: =ROUND((C31/C11),2) | D21: =ROUND((D31/D11),2) | E21: =ROUND((E31/E11),2) | F21: =ROUND((F31/F11),2)
A22: 平均工资 | C22: =AVERAGE(C17:C21) | D22: =AVERAGE(D17:D21) | E22: =AVERAGE(E17:E21) | F22: =AVERAGE(F17:F21) | G22: =AVERAGE(G17:G21) | H22: =AVERAGE(H17:H21) | I22: =AVERAGE(I17:I21) | J22: =AVERAGE(J17:J21) | ... M22: =AVERAGE(M17:M21)
A24: 三、工资总额
A25: 人员类别 | B25: 核算科目 | C25: 历史数据 | G25: 未来预测
C26: 2022年度 | D26: 2023年度 | E26: 2024年度 | F26: 2025年1-6月 | G26: 2025年7-12月 | H26: 2026年度 | I26: 2027年度 | J26: 2028年度 | K26: 2029年度 | L26: 2030年度 | M26: 永续年度
A27: 生产人员 | B27: 营业成本 | G27: =ROUND(G7*G17,2) | H27: =ROUND(H7*H17,2) | I27: =ROUND(I7*I17,2) | J27: =ROUND(J7*J17,2) | K27: =ROUND(K7*K17,2) | L27: =ROUND(L7*L17,2) | M27: =ROUND(M7*M17,2)
A28: 制造人员 | B28: 制造费用 | C28: =制造费用表!C6 | D28: =制造费用表!D6 | E28: =制造费用表!E6 | F28: =制造费用表!F6 | G28: =ROUND(G8*G18,2) | H28: =ROUND(H8*H18,2) | I28: =ROUND(I8*I18,2) | J28: =ROUND(J8*J18,2) | K28: =ROUND(K8*K18,2) | L28: =ROUND(L8*L18,2) | M28: =ROUND(M8*M18,2)
A29: 销售人员 | B29: 销售费用 | C29: =销售费用表!C6 | D29: =销售费用表!D6 | E29: =销售费用表!E6 | F29: =销售费用表!F6 | G29: =ROUND(G9*G19,2) | H29: =ROUND(H9*H19,2) | I29: =ROUND(I9*I19,2) | J29: =ROUND(J9*J19,2) | K29: =ROUND(K9*K19,2) | L29: =ROUND(L9*L19,2) | M29: =ROUND(M9*M19,2)
A30: 管理人员及其他人员 | B30: 管理费用 | C30: =管理费用表!C6 | D30: =管理费用表!D6 | E30: =管理费用表!E6 | F30: =管理费用表!F6 | G30: =ROUND(G10*G20,2) | H30: =ROUND(H10*H20,2) | I30: =ROUND(I10*I20,2) | J30: =ROUND(J10*J20,2) | K30: =ROUND(K10*K20,2) | L30: =ROUND(L10*L20,2) | M30: =ROUND(M10*M20,2)
A31: 研发人员 | B31: 研发费用 | C31: =研发费用表!C6 | D31: =研发费用表!D6 | E31: =研发费用表!E6 | F31: =研发费用表!F6 | G31: =ROUND(G11*G21,2) | H31: =ROUND(H11*H21,2) | I31: =ROUND(I11*I21,2) | J31: =ROUND(J11*J21,2) | K31: =ROUND(K11*K21,2) | L31: =ROUND(L11*L21,2) | M31: =ROUND(M11*M21,2)
A32: 工资总额合计 | C32: =SUM(C27:C31) | D32: =SUM(D27:D31) | E32: =SUM(E27:E31) | F32: =SUM(F27:F31) | G32: =SUM(G27:G31) | H32: =SUM(H27:H31) | I32: =SUM(I27:I31) | J32: =SUM(J27:J31) | ... M32: =SUM(M27:M31)

Sheet 制造费用表
A1: 制造费用分析预测表 | N1: =HYPERLINK("#目录1!A1","返回目录")
A2: 评估基准日：{{VALUATION_BASE_DATE}}
A3: ="被评估单位："&项目信息!B5&"" | M3: ="金额单位："&项目信息!B8&""
A4: 项目 | C4: 历史数据 | G4: 未来预测
C5: 2022年度 | D5: 2023年度 | E5: 2024年度 | F5: 2025年1-6月 | G5: 2025年7-12月 | H5: 2026年度 | I5: 2027年度 | J5: 2028年度 | K5: 2029年度 | L5: 2030年度 | M5: 永续年度
A6: 人工
A7: 材料
A8: 折旧 | G8: =折旧摊销、资本性支出表!G9 | H8: =折旧摊销、资本性支出表!H9 | I8: =折旧摊销、资本性支出表!I9 | J8: =折旧摊销、资本性支出表!J9 | K8: =折旧摊销、资本性支出表!K9 | L8: =折旧摊销、资本性支出表!L9 | M8: =折旧摊销、资本性支出表!M9
A9: 摊销 | G9: =折旧摊销、资本性支出表!G10 | H9: =折旧摊销、资本性支出表!H10 | I9: =折旧摊销、资本性支出表!I10 | J9: =折旧摊销、资本性支出表!J10 | K9: =折旧摊销、资本性支出表!K10 | L9: =折旧摊销、资本性支出表!L10 | M9: =折旧摊销、资本性支出表!M10
A10: 业务招待费
A11: 使用权资产折旧
A12: 房屋租赁费
A13: 运输费
A62: 合计 | C62: =SUM(C6:C61) | D62: =SUM(D6:D61) | E62: =SUM(E6:E61) | F62: =SUM(F6:F61) | G62: =SUM(G6:G61) | H62: =SUM(H6:H61) | I62: =SUM(I6:I61) | J62: =SUM(J6:J61) | ... M62: =SUM(M6:M61)
A64: 增长率（%） | D64: =ROUND((D62-C62)/C62,4) | E64: =ROUND((E62-D62)/D62,4) | F64: =ROUND((F62/6*12-E62)/E62,4) | G64: =ROUND((G62+F62-E62)/E62,4) | H64: =ROUND((H62-(G62+F62))/(G62+F62),4) | I64: =ROUND((I62-H62)/H62,4) | J64: =ROUND((J62-I62)/I62,4) | K64: =ROUND((K62-J62)/J62,4) | L64: =ROUND((L62-K62)/K62,4) | M64: =ROUND((M62-L62)/L62,4)
A65: 占主营业务收入的比例（%） | C65: =ROUND(C62/营业收入表!C11,4) | D65: =ROUND(D62/营业收入表!D11,4) | E65: =ROUND(E62/营业收入表!E11,4) | F65: =ROUND(F62/营业收入表!F11,4) | G65: =ROUND(G62/营业收入表!G11,4) | H65: =ROUND(H62/营业收入表!H11,4) | I65: =ROUND(I62/营业收入表!I11,4) | J65: =ROUND(J62/营业收入表!J11,4) | ... M65: =ROUND(M62/营业收入表!M11,4)
A66: 占营业收入比例（%） | C66: =ROUND(C62/营业收入表!C17,4) | D66: =ROUND(D62/营业收入表!D17,4) | E66: =ROUND(E62/营业收入表!E17,4) | F66: =ROUND(F62/营业收入表!F17,4) | G66: =ROUND(G62/营业收入表!G17,4) | H66: =ROUND(H62/营业收入表!H17,4) | I66: =ROUND(I62/营业收入表!I17,4) | J66: =ROUND(J62/营业收入表!J17,4) | ... M66: =ROUND(M62/营业收入表!M17,4)
A67: 人工核对 | C67: =C6-人工成本表!C28 | D67: =D6-人工成本表!D28 | E67: =E6-人工成本表!E28 | F67: =F6-人工成本表!F28 | G67: =G6-人工成本表!G28 | H67: =H6-人工成本表!H28 | I67: =I6-人工成本表!I28 | J67: =J6-人工成本表!J28 | ... M67: =M6-人工成本表!M28

Sheet 税金及附加表
A1: 税金及附加分析预测表 | N1: =HYPERLINK("#目录1!A1","返回目录")
A2: 评估基准日：{{VALUATION_BASE_DATE}}
A3: ="被评估单位："&项目信息!B5&"" | M3: ="金额单位："&项目信息!B8&""
A4: 税种 | B4: 税率（%） | C4: 历史数据 | G4: 未来预测
C5: 2022年度 | D5: 2023年度 | E5: 2024年度 | F5: 2025年1-6月 | G5: 2025年7-12月 | H5: 2026年度 | I5: 2027年度 | J5: 2028年度 | K5: 2029年度 | L5: 2030年度 | M5: 永续年度
A6: 城建税 | G6: =IF(增值税表!G162>0,ROUND(增值税表!G162*税金及附加表!B6,2),0) | H6: =IF(增值税表!H162>0,ROUND(增值税表!H162*税金及附加表!B6,2),0) | I6: =IF(增值税表!I162>0,ROUND(增值税表!I162*税金及附加表!B6,2),0) | J6: =IF(增值税表!J162>0,ROUND(增值税表!J162*税金及附加表!B6,2),0) | K6: =IF(增值税表!K162>0,ROUND(增值税表!K162*税金及附加表!B6,2),0) | L6: =IF(增值税表!L162>0,ROUND(增值税表!L162*税金及附加表!B6,2),0) | M6: =IF(增值税表!M162>0,ROUND(增值税表!M162*税金及附加表!B6,2),0)
A7: 教育费附加 | G7: =IF(增值税表!G162>0,ROUND(增值税表!G162*税金及附加表!B7,2),0) | H7: =IF(增值税表!H162>0,ROUND(增值税表!H162*税金及附加表!B7,2),0) | I7: =IF(增值税表!I162>0,ROUND(增值税表!I162*税金及附加表!B7,2),0) | J7: =IF(增值税表!J162>0,ROUND(增值税表!J162*税金及附加表!B7,2),0) | K7: =IF(增值税表!K162>0,ROUND(增值税表!K162*税金及附加表!B7,2),0) | L7: =IF(增值税表!L162>0,ROUND(增值税表!L162*税金及附加表!B7,2),0) | M7: =IF(增值税表!M162>0,ROUND(增值税表!M162*税金及附加表!B7,2),0)
A8: 地方教育费附加 | G8: =IF(增值税表!G162>0,ROUND(增值税表!G162*税金及附加表!B8,2),0) | H8: =IF(增值税表!H162>0,ROUND(增值税表!H162*税金及附加表!B8,2),0) | I8: =IF(增值税表!I162>0,ROUND(增值税表!I162*税金及附加表!B8,2),0) | J8: =IF(增值税表!J162>0,ROUND(增值税表!J162*税金及附加表!B8,2),0) | K8: =IF(增值税表!K162>0,ROUND(增值税表!K162*税金及附加表!B8,2),0) | L8: =IF(增值税表!L162>0,ROUND(增值税表!L162*税金及附加表!B8,2),0) | M8: =IF(增值税表!M162>0,ROUND(增值税表!M162*税金及附加表!B8,2),0)
A9: 印花税
A10: 房产税
A11: 土地使用税
A12: 车船使用税
A13: 环保税
A14: 消费税
A27: 合计 | C27: =SUM(C6:C26) | D27: =SUM(D6:D26) | E27: =SUM(E6:E26) | F27: =SUM(F6:F26) | G27: =SUM(G6:G26) | H27: =SUM(H6:H26) | I27: =SUM(I6:I26) | J27: =SUM(J6:J26) | ... M27: =SUM(M6:M26)
A29: 【HD】核对 | C29: =C27-历利调整后表!D24 | D29: =D27-历利调整后表!G24 | E29: =E27-历利调整后表!J24 | F29: =F27-历利调整后表!M24
A30: 占主营业务收入的比例（%） | C30: =ROUND(C27/营业收入表!C11,4) | D30: =ROUND(D27/营业收入表!D11,4) | E30: =ROUND(E27/营业收入表!E11,4) | F30: =ROUND(F27/营业收入表!F11,4) | G30: =ROUND(G27/营业收入表!G11,4) | H30: =ROUND(H27/营业收入表!H11,4) | I30: =ROUND(I27/营业收入表!I11,4) | J30: =ROUND(J27/营业收入表!J11,4) | ... M30: =ROUND(M27/营业收入表!M11,4)
A31: 占营业收入比例（%） | C31: =ROUND(C27/营业收入表!C17,4) | D31: =ROUND(D27/营业收入表!D17,4) | E31: =ROUND(E27/营业收入表!E17,4) | F31: =ROUND(F27/营业收入表!F17,4) | G31: =ROUND(G27/营业收入表!G17,4) | H31: =ROUND(H27/营业收入表!H17,4) | I31: =ROUND(I27/营业收入表!I17,4) | J31: =ROUND(J27/营业收入表!J17,4) | ... M31: =ROUND(M27/营业收入表!M17,4)

Sheet 增值税表
A1: 增值税预测表 | N1: =HYPERLINK("#目录1!A1","返回目录")
A2: 评估基准日：{{VALUATION_BASE_DATE}}
A3: ="被评估单位："&项目信息!B5&"" | M3: ="金额单位："&项目信息!B8&""
A4: 类别 | B4: 税率 | C4: 历史数据 | G4: 未来预测
C5: 2022年度 | D5: 2023年度 | E5: 2024年度 | F5: 2025年1-6月 | G5: 2025年7-12月 | H5: 2026年度 | I5: 2027年度 | J5: 2028年度 | K5: 2029年度 | L5: 2030年度 | M5: 永续年度
A6: 主营业务收入：
A7: 金额 | M7: =L7
A8: 销项税 | B8: 13.00% | C8: =ROUND($B8*C7,2) | D8: =ROUND($B8*D7,2) | E8: =ROUND($B8*E7,2) | F8: =ROUND($B8*F7,2) | G8: =ROUND($B8*G7,2) | H8: =ROUND($B8*H7,2) | I8: =ROUND($B8*I7,2) | J8: =ROUND($B8*J7,2) | ... M8: =ROUND($B8*M7,2)
A9: 金额
A10: 销项税 | B10: 9.00% | C10: =ROUND($B10*C9,2) | D10: =ROUND($B10*D9,2) | E10: =ROUND($B10*E9,2) | F10: =ROUND($B10*F9,2) | G10: =ROUND($B10*G9,2) | H10: =ROUND($B10*H9,2) | I10: =ROUND($B10*I9,2) | J10: =ROUND($B10*J9,2) | ... M10: =ROUND($B10*M9,2)
A11: 金额
A12: 销项税 | B12: 6.00% | C12: =ROUND($B12*C11,2) | D12: =ROUND($B12*D11,2) | E12: =ROUND($B12*E11,2) | F12: =ROUND($B12*F11,2) | G12: =ROUND($B12*G11,2) | H12: =ROUND($B12*H11,2) | I12: =ROUND($B12*I11,2) | J12: =ROUND($B12*J11,2) | ... M12: =ROUND($B12*M11,2)
A13: 金额
A14: 销项税 | C14: =ROUND($B14*C13,2) | D14: =ROUND($B14*D13,2) | E14: =ROUND($B14*E13,2) | F14: =ROUND($B14*F13,2) | G14: =ROUND($B14*G13,2) | H14: =ROUND($B14*H13,2) | I14: =ROUND($B14*I13,2) | J14: =ROUND($B14*J13,2) | ... M14: =ROUND($B14*M13,2)
A15: 金额
A16: 销项税 | C16: =ROUND($B16*C15,2) | D16: =ROUND($B16*D15,2) | E16: =ROUND($B16*E15,2) | F16: =ROUND($B16*F15,2) | G16: =ROUND($B16*G15,2) | H16: =ROUND($B16*H15,2) | I16: =ROUND($B16*I15,2) | J16: =ROUND($B16*J15,2) | ... M16: =ROUND($B16*M15,2)
A17: 金额
A18: 销项税 | C18: =ROUND($B18*C17,2) | D18: =ROUND($B18*D17,2) | E18: =ROUND($B18*E17,2) | F18: =ROUND($B18*F17,2) | G18: =ROUND($B18*G17,2) | H18: =ROUND($B18*H17,2) | I18: =ROUND($B18*I17,2) | J18: =ROUND($B18*J17,2) | ... M18: =ROUND($B18*M17,2)
A19: 金额
A20: 销项税 | C20: =ROUND($B20*C19,2) | D20: =ROUND($B20*D19,2) | E20: =ROUND($B20*E19,2) | F20: =ROUND($B20*F19,2) | G20: =ROUND($B20*G19,2) | H20: =ROUND($B20*H19,2) | I20: =ROUND($B20*I19,2) | J20: =ROUND($B20*J19,2) | ... M20: =ROUND($B20*M19,2)
A21: 金额
A22: 销项税 | C22: =ROUND($B22*C21,2) | D22: =ROUND($B22*D21,2) | E22: =ROUND($B22*E21,2) | F22: =ROUND($B22*F21,2) | G22: =ROUND($B22*G21,2) | H22: =ROUND($B22*H21,2) | I22: =ROUND($B22*I21,2) | J22: =ROUND($B22*J21,2) | ... M22: =ROUND($B22*M21,2)
A23: 其他业务收入：
A24: 金额
A25: 销项税 | B25: 13.00% | C25: =ROUND($B25*C24,2) | D25: =ROUND($B25*D24,2) | E25: =ROUND($B25*E24,2) | F25: =ROUND($B25*F24,2) | G25: =ROUND($B25*G24,2) | H25: =ROUND($B25*H24,2) | I25: =ROUND($B25*I24,2) | J25: =ROUND($B25*J24,2) | ... M25: =ROUND($B25*M24,2)
A26: 金额
A27: 销项税 | B27: 9.00% | C27: =ROUND($B27*C26,2) | D27: =ROUND($B27*D26,2) | E27: =ROUND($B27*E26,2) | F27: =ROUND($B27*F26,2) | G27: =ROUND($B27*G26,2) | H27: =ROUND($B27*H26,2) | I27: =ROUND($B27*I26,2) | J27: =ROUND($B27*J26,2) | ... M27: =ROUND($B27*M26,2)
A28: 金额
A29: 销项税 | B29: 6.00% | C29: =ROUND($B29*C28,2) | D29: =ROUND($B29*D28,2) | E29: =ROUND($B29*E28,2) | F29: =ROUND($B29*F28,2) | G29: =ROUND($B29*G28,2) | H29: =ROUND($B29*H28,2) | I29: =ROUND($B29*I28,2) | J29: =ROUND($B29*J28,2) | ... M29: =ROUND($B29*M28,2)
A30: 金额
A31: 销项税 | C31: =ROUND($B31*C30,2) | D31: =ROUND($B31*D30,2) | E31: =ROUND($B31*E30,2) | F31: =ROUND($B31*F30,2) | G31: =ROUND($B31*G30,2) | H31: =ROUND($B31*H30,2) | I31: =ROUND($B31*I30,2) | J31: =ROUND($B31*J30,2) | ... M31: =ROUND($B31*M30,2)
A32: 金额
A33: 销项税 | C33: =ROUND($B33*C32,2) | D33: =ROUND($B33*D32,2) | E33: =ROUND($B33*E32,2) | F33: =ROUND($B33*F32,2) | G33: =ROUND($B33*G32,2) | H33: =ROUND($B33*H32,2) | I33: =ROUND($B33*I32,2) | J33: =ROUND($B33*J32,2) | ... M33: =ROUND($B33*M32,2)
A34: 金额
A35: 销项税 | C35: =ROUND($B35*C34,2) | D35: =ROUND($B35*D34,2) | E35: =ROUND($B35*E34,2) | F35: =ROUND($B35*F34,2) | G35: =ROUND($B35*G34,2) | H35: =ROUND($B35*H34,2) | I35: =ROUND($B35*I34,2) | J35: =ROUND($B35*J34,2) | ... M35: =ROUND($B35*M34,2)
A36: 金额
A37: 销项税 | C37: =ROUND($B37*C36,2) | D37: =ROUND($B37*D36,2) | E37: =ROUND($B37*E36,2) | F37: =ROUND($B37*F36,2) | G37: =ROUND($B37*G36,2) | H37: =ROUND($B37*H36,2) | I37: =ROUND($B37*I36,2) | J37: =ROUND($B37*J36,2) | ... M37: =ROUND($B37*M36,2)
A38: 金额
A39: 销项税 | C39: =ROUND($B39*C38,2) | D39: =ROUND($B39*D38,2) | E39: =ROUND($B39*E38,2) | F39: =ROUND($B39*F38,2) | G39: =ROUND($B39*G38,2) | H39: =ROUND($B39*H38,2) | I39: =ROUND($B39*I38,2) | J39: =ROUND($B39*J38,2) | ... M39: =ROUND($B39*M38,2)
A40: 销项税合计 | C40: =SUMIF($A6:$A39,$A8,C6:C39) | D40: =SUMIF($A6:$A39,$A8,D6:D39) | E40: =SUMIF($A6:$A39,$A8,E6:E39) | F40: =SUMIF($A6:$A39,$A8,F6:F39) | G40: =SUMIF($A6:$A39,$A8,G6:G39) | H40: =SUMIF($A6:$A39,$A8,H6:H39) | I40: =SUMIF($A6:$A39,$A8,I6:I39) | J40: =SUMIF($A6:$A39,$A8,J6:J39) | ... M40: =SUMIF($A6:$A39,$A8,M6:M39)
...

Sheet 销售费用表
A1: 销售费用分析预测表 | N1: =HYPERLINK("#目录1!A1","返回目录")
A2: 评估基准日：{{VALUATION_BASE_DATE}}
A3: ="被评估单位："&项目信息!B5&"" | M3: ="金额单位："&项目信息!B8&""
A4: 项目 | C4: 历史数据 | G4: 未来预测
C5: 2022年度 | D5: 2023年度 | E5: 2024年度 | F5: 2025年1-6月 | G5: 2025年7-12月 | H5: 2026年度 | I5: 2027年度 | J5: 2028年度 | K5: 2029年度 | L5: 2030年度 | M5: 永续年度
A6: 人工
